Workbook
Name RENT: Главная!$B$9
Name DEPOSIT: Главная!$E$9
Name DOG_DATE: Главная!$B$7
Name TERM_M: Главная!$E$7
Name PAY_DAY: Главная!$B$10
Name END_DATE: Главная!$B$8
Name TAX_RATE: Справочники!$B$5
Name COMM_PLAN: Справочники!$B$6
Name REMIND_D: Справочники!$B$7
Name L_CAT: Справочники!$A$11:$A$15
Name L_PAY: Справочники!$C$11:$C$16
Name L_PER: История!$A$6:$A$41
Name J_DATE: Регистрация!$B$7:$B$306
Name J_CAT: Регистрация!$C$7:$C$306
Name J_PER: Регистрация!$I$7:$I$306
Name J_SUM: Регистрация!$E$7:$E$306
Name J_PAY: Регистрация!$F$7:$F$306

Sheet Главная
A1: ЖУРНАЛ АРЕНДНЫХ ПЛАТЕЖЕЙ
A2: =IF(B5="","Заполните карточку договора ниже · все итоги считаются автоматически",B5&" • "&IF(B6="","наниматель не указан",B6))
A4: КАРТОЧКА ДОГОВОРА
A5: Адрес
A6: Наниматель
A7: Дата договора | D7: Срок (мес.)
A8: 🤖 Дата окончания | B8: =IF(OR($B$7="",$E$7=""),"",EDATE($B$7,$E$7)-1) | D8: 🤖 Осталось дней | E8: =IF($B$8="","",IF($B$8<TODAY(),"договор истёк",MAX(0,$B$8-TODAY())&" дн."))
A9: Размер аренды | D9: Размер залога
A10: День платежа | D10: 🤖 Следующий платеж | E10: =IF(COUNTIF(История!$F$6:$F$41,">0")=0,"нет долгов",_xlfn.MINIFS(История!$B$6:$B$41,История!$F$6:$F$41,">0"))
A11: 🤖 Статус | B11: =IF($B$7="","Договор не заполнен — начните с карточки выше",IF(SUMIF(История!$F$6:$F$41,">0")>0,"⚠ Задолженность: "&TEXT(SUMIF(История!$F$6:$F$41,">0"),"#,##0")&" ₽","✔ Задолженности нет — все платежи в срок"))
A13: ФИНАНСЫ · ИТОГИ ПО ПОЗИЦИЯМ
A15: 🏠 ОПЛАЧЕНО ЗА АРЕНДУ | D15: 🧾 ОПЛАЧЕНО НАЛОГОВ
A16: =SUMIFS(J_SUM,J_CAT,"Аренда") | D16: =SUMIFS(J_SUM,J_CAT,"Налог")
A17: ="Платежей: "&COUNTIFS(J_CAT,"Аренда")&" • всего по договору: "&TEXT(IFERROR($B$9*$E$7,0),"#,##0")&" ₽" | D17: ="Платежей: "&COUNTIFS(J_CAT,"Налог")&" • расчёт от аренды: "&TEXT(SUMIFS(J_SUM,J_CAT,"Аренда")*TAX_RATE,"#,##0")&" ₽"
A19: 💡 ОПЛАЧЕНО ЗА КОММУНАЛЬНЫЕ УСЛУГИ | D19: 🔐 ОПЛАТА ЗАЛОГА
A20: =SUMIFS(J_SUM,J_CAT,"Коммунальные услуги") | D20: =SUMIFS(J_SUM,J_CAT,"Залог")
A21: ="Платежей: "&COUNTIFS(J_CAT,"Коммунальные услуги")&" • в среднем: "&TEXT(IFERROR(AVERAGEIFS(J_SUM,J_CAT,"Коммунальные услуги"),0),"#,##0")&" ₽" | D21: ="По договору: "&TEXT($E$9,"#,##0")&" ₽ • "&IF(SUMIFS(J_SUM,J_CAT,"Залог")>=$E$9,"✔ внесён полностью","осталось "&TEXT($E$9-SUMIFS(J_SUM,J_CAT,"Залог"),"#,##0")&" ₽")
A23: СВОДКА
A24: Итого оплачено (все позиции) | B24: =SUM(J_SUM) | D24: Оплачено в текущем году | E24: =SUMIFS(J_SUM,J_PER,">="&DATE(YEAR(TODAY()),1,1),J_PER,"<="&DATE(YEAR(TODAY()),12,31))
A25: Текущий долг по аренде | B25: =SUMIF(История!$F$6:$F$41,">0") | D25: Записей в журнале | E25: =COUNT(J_SUM)
A27: КАК ПОЛЬЗОВАТЬСЯ
A28: 1. Заполните карточку договора — поля с бирюзовой рамкой (белый фон) открыты для ввода.
A29: 2. Каждый платёж вносите на листе «Регистрация»: дата, категория, сумма — месяц подставится сам.
A30: 3. Листы «История» и «Аналитика» и карточки итогов пересчитываются сами — их не трогаем.
A31: 4. Сиреневые ячейки 🤖 — формулы, их заполнять не нужно.
A32: 5. Если ввод не вставляется — вверху Excel нажмите «Разрешить редактирование» (жёлтая полоса «Защищённый просмотр») и сохраните файл на компьютер.

Sheet Регистрация
A1: РЕГИСТРАЦИЯ ПЛАТЕЖЕЙ
A2: Одна строка — один платёж. Достаточно заполнить: Дата · Категория · Сумма — месяц подставится сам. Не вставляется значение? Нажмите «Разрешить редактирование» вверху Excel
A4: ="Записей: "&COUNT($E$7:$E$306) | C4: ="Сумма: "&TEXT(SUM($E$7:$E$306),"#,##0")&" ₽" | E4: ="Последняя запись:" | F4: =IF(COUNT($B$7:$B$306)=0,"—",MAX($B$7:$B$306)) | G4: ="Предупреждений: "&COUNTIF($H$7:$H$306,"⚠*")
A6: № | B6: Дата | C6: Категория | D6: Месяц (необяз.) | E6: Сумма | F6: Способ | G6: Комментарий | H6: 🤖 Контроль | I6: 🤖 Учтён за месяц
A7: =IF(B7="","",ROW()-6) | H7: =IF(COUNTA(B7:G7)=0,"",IF(B7="","⚠ нет даты",IF(C7="","⚠ нет категории",IF(NOT(ISNUMBER(E7)),"⚠ нет суммы",IF(E7<=0,"⚠ сумма ≤ 0",IF(AND(Главная!$B$7<>"",B7<Главная!$B$7),"⚠ дата до договора",IF(B7>TODAY(),"ⓘ будущая дата","✓ ОК"))))))) | I7: =IF(COUNTA(B7:G7)=0,"",IF(D7<>"",D7,IF(B7="","",DATE(YEAR(B7),MONTH(B7),1))))
A8: =IF(B8="","",ROW()-6) | H8: =IF(COUNTA(B8:G8)=0,"",IF(B8="","⚠ нет даты",IF(C8="","⚠ нет категории",IF(NOT(ISNUMBER(E8)),"⚠ нет суммы",IF(E8<=0,"⚠ сумма ≤ 0",IF(AND(Главная!$B$7<>"",B8<Главная!$B$7),"⚠ дата до договора",IF(B8>TODAY(),"ⓘ будущая дата","✓ ОК"))))))) | I8: =IF(COUNTA(B8:G8)=0,"",IF(D8<>"",D8,IF(B8="","",DATE(YEAR(B8),MONTH(B8),1))))
A9: =IF(B9="","",ROW()-6) | H9: =IF(COUNTA(B9:G9)=0,"",IF(B9="","⚠ нет даты",IF(C9="","⚠ нет категории",IF(NOT(ISNUMBER(E9)),"⚠ нет суммы",IF(E9<=0,"⚠ сумма ≤ 0",IF(AND(Главная!$B$7<>"",B9<Главная!$B$7),"⚠ дата до договора",IF(B9>TODAY(),"ⓘ будущая дата","✓ ОК"))))))) | I9: =IF(COUNTA(B9:G9)=0,"",IF(D9<>"",D9,IF(B9="","",DATE(YEAR(B9),MONTH(B9),1))))
A10: =IF(B10="","",ROW()-6) | H10: =IF(COUNTA(B10:G10)=0,"",IF(B10="","⚠ нет даты",IF(C10="","⚠ нет категории",IF(NOT(ISNUMBER(E10)),"⚠ нет суммы",IF(E10<=0,"⚠ сумма ≤ 0",IF(AND(Главная!$B$7<>"",B10<Главная!$B$7),"⚠ дата до договора",IF(B10>TODAY(),"ⓘ будущая дата","✓ ОК"))))))) | I10: =IF(COUNTA(B10:G10)=0,"",IF(D10<>"",D10,IF(B10="","",DATE(YEAR(B10),MONTH(B10),1))))
A11: =IF(B11="","",ROW()-6) | H11: =IF(COUNTA(B11:G11)=0,"",IF(B11="","⚠ нет даты",IF(C11="","⚠ нет категории",IF(NOT(ISNUMBER(E11)),"⚠ нет суммы",IF(E11<=0,"⚠ сумма ≤ 0",IF(AND(Главная!$B$7<>"",B11<Главная!$B$7),"⚠ дата до договора",IF(B11>TODAY(),"ⓘ будущая дата","✓ ОК"))))))) | I11: =IF(COUNTA(B11:G11)=0,"",IF(D11<>"",D11,IF(B11="","",DATE(YEAR(B11),MONTH(B11),1))))
A12: =IF(B12="","",ROW()-6) | H12: =IF(COUNTA(B12:G12)=0,"",IF(B12="","⚠ нет даты",IF(C12="","⚠ нет категории",IF(NOT(ISNUMBER(E12)),"⚠ нет суммы",IF(E12<=0,"⚠ сумма ≤ 0",IF(AND(Главная!$B$7<>"",B12<Главная!$B$7),"⚠ дата до договора",IF(B12>TODAY(),"ⓘ будущая дата","✓ ОК"))))))) | I12: =IF(COUNTA(B12:G12)=0,"",IF(D12<>"",D12,IF(B12="","",DATE(YEAR(B12),MONTH(B12),1))))
A13: =IF(B13="","",ROW()-6) | H13: =IF(COUNTA(B13:G13)=0,"",IF(B13="","⚠ нет даты",IF(C13="","⚠ нет категории",IF(NOT(ISNUMBER(E13)),"⚠ нет суммы",IF(E13<=0,"⚠ сумма ≤ 0",IF(AND(Главная!$B$7<>"",B13<Главная!$B$7),"⚠ дата до договора",IF(B13>TODAY(),"ⓘ будущая дата","✓ ОК"))))))) | I13: =IF(COUNTA(B13:G13)=0,"",IF(D13<>"",D13,IF(B13="","",DATE(YEAR(B13),MONTH(B13),1))))
A14: =IF(B14="","",ROW()-6) | H14: =IF(COUNTA(B14:G14)=0,"",IF(B14="","⚠ нет даты",IF(C14="","⚠ нет категории",IF(NOT(ISNUMBER(E14)),"⚠ нет суммы",IF(E14<=0,"⚠ сумма ≤ 0",IF(AND(Главная!$B$7<>"",B14<Главная!$B$7),"⚠ дата до договора",IF(B14>TODAY(),"ⓘ будущая дата","✓ ОК"))))))) | I14: =IF(COUNTA(B14:G14)=0,"",IF(D14<>"",D14,IF(B14="","",DATE(YEAR(B14),MONTH(B14),1))))
A15: =IF(B15="","",ROW()-6) | H15: =IF(COUNTA(B15:G15)=0,"",IF(B15="","⚠ нет даты",IF(C15="","⚠ нет категории",IF(NOT(ISNUMBER(E15)),"⚠ нет суммы",IF(E15<=0,"⚠ сумма ≤ 0",IF(AND(Главная!$B$7<>"",B15<Главная!$B$7),"⚠ дата до договора",IF(B15>TODAY(),"ⓘ будущая дата","✓ ОК"))))))) | I15: =IF(COUNTA(B15:G15)=0,"",IF(D15<>"",D15,IF(B15="","",DATE(YEAR(B15),MONTH(B15),1))))
A16: =IF(B16="","",ROW()-6) | H16: =IF(COUNTA(B16:G16)=0,"",IF(B16="","⚠ нет даты",IF(C16="","⚠ нет категории",IF(NOT(ISNUMBER(E16)),"⚠ нет суммы",IF(E16<=0,"⚠ сумма ≤ 0",IF(AND(Главная!$B$7<>"",B16<Главная!$B$7),"⚠ дата до договора",IF(B16>TODAY(),"ⓘ будущая дата","✓ ОК"))))))) | I16: =IF(COUNTA(B16:G16)=0,"",IF(D16<>"",D16,IF(B16="","",DATE(YEAR(B16),MONTH(B16),1))))
A17: =IF(B17="","",ROW()-6) | H17: =IF(COUNTA(B17:G17)=0,"",IF(B17="","⚠ нет даты",IF(C17="","⚠ нет категории",IF(NOT(ISNUMBER(E17)),"⚠ нет суммы",IF(E17<=0,"⚠ сумма ≤ 0",IF(AND(Главная!$B$7<>"",B17<Главная!$B$7),"⚠ дата до договора",IF(B17>TODAY(),"ⓘ будущая дата","✓ ОК"))))))) | I17: =IF(COUNTA(B17:G17)=0,"",IF(D17<>"",D17,IF(B17="","",DATE(YEAR(B17),MONTH(B17),1))))
A18: =IF(B18="","",ROW()-6) | H18: =IF(COUNTA(B18:G18)=0,"",IF(B18="","⚠ нет даты",IF(C18="","⚠ нет категории",IF(NOT(ISNUMBER(E18)),"⚠ нет суммы",IF(E18<=0,"⚠ сумма ≤ 0",IF(AND(Главная!$B$7<>"",B18<Главная!$B$7),"⚠ дата до договора",IF(B18>TODAY(),"ⓘ будущая дата","✓ ОК"))))))) | I18: =IF(COUNTA(B18:G18)=0,"",IF(D18<>"",D18,IF(B18="","",DATE(YEAR(B18),MONTH(B18),1))))
... A306: =IF(B306="","",ROW()-6) | H306: =IF(COUNTA(B306:G306)=0,"",IF(B306="","⚠ нет даты",IF(C306="","⚠ нет категории",IF(NOT(ISNUMBER(E306)),"⚠ нет суммы",IF(E306<=0,"⚠ сумма ≤ 0",IF(AND(Главная!$B$7<>"",B306<Главная!$B$7),"⚠ дата до договора",IF(B306>TODAY(),"ⓘ будущая дата","✓ ОК"))))))) | I306: =IF(COUNTA(B306:G306)=0,"",IF(D306<>"",D306,IF(B306="","",DATE(YEAR(B306),MONTH(B306),1))))
A307: ИТОГО ПО ЖУРНАЛУ | E307: =SUM(E7:E306) | F307: ="записей: "&COUNT(E7:E306)

Sheet История
A1: ИСТОРИЯ НАЧИСЛЕНИЙ И ОПЛАТ
A2: Лист считается автоматически по данным журнала «Регистрация» — ручной ввод не требуется
A4: ="Начислено на сегодня: "&TEXT(SUM($D$6:$D$41),"#,##0")&" ₽" | C4: ="Оплачено: "&TEXT(SUM($E$6:$E$41),"#,##0")&" ₽" | E4: ="Текущий долг: "&TEXT(SUMIF($F$6:$F$41,">0"),"#,##0")&" ₽" | G4: ="Закрыто: "&COUNTIF($G$6:$G$41,"✔*")&" мес."
A5: Месяц | B5: Срок | C5: Дата | D5: Начислено | E5: Оплачено | F5: Долг | G5: Статус
A6: =IF(OR(Главная!$B$7="",1>IFERROR(Главная!$E$7,0)),"",DATE(YEAR(EDATE(Главная!$B$7,0)),MONTH(EDATE(Главная!$B$7,0)),1)) | B6: =IF($A6="","",MIN($A6+MAX(1,IFERROR(Главная!$B$10,1))-1,EOMONTH($A6,0))) | C6: =IF($A6="","",IF(_xlfn.MAXIFS(J_DATE,J_PER,$A6,J_CAT,"Аренда")=0,"",_xlfn.MAXIFS(J_DATE,J_PER,$A6,J_CAT,"Аренда"))) | D6: =IF($A6="","",IF(AND(1<=IFERROR(Главная!$E$7,0),$A6<=TODAY()),IFERROR(Главная!$B$9,0),0)) | E6: =IF($A6="","",SUMIFS(J_SUM,J_PER,$A6,J_CAT,"Аренда")) | F6: =IF($A6="","",$D6-$E6) | G6: =IF($A6="","",IF($D6=0,IF($E6>0,"✔ Оплачено авансом","⏳ Ожидается"),IF($E6>=$D6,"✔ Оплачено",IF(AND($E6>0,TODAY()>$B6),"◐ Частично, просрочено",IF($E6>0,"◐ Частично",IF(TODAY()>$B6,"⚠ Просрочено","⏳ Ожидается"))))))
A7: =IF(OR(Главная!$B$7="",2>IFERROR(Главная!$E$7,0)),"",DATE(YEAR(EDATE(Главная!$B$7,1)),MONTH(EDATE(Главная!$B$7,1)),1)) | B7: =IF($A7="","",MIN($A7+MAX(1,IFERROR(Главная!$B$10,1))-1,EOMONTH($A7,0))) | C7: =IF($A7="","",IF(_xlfn.MAXIFS(J_DATE,J_PER,$A7,J_CAT,"Аренда")=0,"",_xlfn.MAXIFS(J_DATE,J_PER,$A7,J_CAT,"Аренда"))) | D7: =IF($A7="","",IF(AND(2<=IFERROR(Главная!$E$7,0),$A7<=TODAY()),IFERROR(Главная!$B$9,0),0)) | E7: =IF($A7="","",SUMIFS(J_SUM,J_PER,$A7,J_CAT,"Аренда")) | F7: =IF($A7="","",$D7-$E7) | G7: =IF($A7="","",IF($D7=0,IF($E7>0,"✔ Оплачено авансом","⏳ Ожидается"),IF($E7>=$D7,"✔ Оплачено",IF(AND($E7>0,TODAY()>$B7),"◐ Частично, просрочено",IF($E7>0,"◐ Частично",IF(TODAY()>$B7,"⚠ Просрочено","⏳ Ожидается"))))))
A8: =IF(OR(Главная!$B$7="",3>IFERROR(Главная!$E$7,0)),"",DATE(YEAR(EDATE(Главная!$B$7,2)),MONTH(EDATE(Главная!$B$7,2)),1)) | B8: =IF($A8="","",MIN($A8+MAX(1,IFERROR(Главная!$B$10,1))-1,EOMONTH($A8,0))) | C8: =IF($A8="","",IF(_xlfn.MAXIFS(J_DATE,J_PER,$A8,J_CAT,"Аренда")=0,"",_xlfn.MAXIFS(J_DATE,J_PER,$A8,J_CAT,"Аренда"))) | D8: =IF($A8="","",IF(AND(3<=IFERROR(Главная!$E$7,0),$A8<=TODAY()),IFERROR(Главная!$B$9,0),0)) | E8: =IF($A8="","",SUMIFS(J_SUM,J_PER,$A8,J_CAT,"Аренда")) | F8: =IF($A8="","",$D8-$E8) | G8: =IF($A8="","",IF($D8=0,IF($E8>0,"✔ Оплачено авансом","⏳ Ожидается"),IF($E8>=$D8,"✔ Оплачено",IF(AND($E8>0,TODAY()>$B8),"◐ Частично, просрочено",IF($E8>0,"◐ Частично",IF(TODAY()>$B8,"⚠ Просрочено","⏳ Ожидается"))))))
A9: =IF(OR(Главная!$B$7="",4>IFERROR(Главная!$E$7,0)),"",DATE(YEAR(EDATE(Главная!$B$7,3)),MONTH(EDATE(Главная!$B$7,3)),1)) | B9: =IF($A9="","",MIN($A9+MAX(1,IFERROR(Главная!$B$10,1))-1,EOMONTH($A9,0))) | C9: =IF($A9="","",IF(_xlfn.MAXIFS(J_DATE,J_PER,$A9,J_CAT,"Аренда")=0,"",_xlfn.MAXIFS(J_DATE,J_PER,$A9,J_CAT,"Аренда"))) | D9: =IF($A9="","",IF(AND(4<=IFERROR(Главная!$E$7,0),$A9<=TODAY()),IFERROR(Главная!$B$9,0),0)) | E9: =IF($A9="","",SUMIFS(J_SUM,J_PER,$A9,J_CAT,"Аренда")) | F9: =IF($A9="","",$D9-$E9) | G9: =IF($A9="","",IF($D9=0,IF($E9>0,"✔ Оплачено авансом","⏳ Ожидается"),IF($E9>=$D9,"✔ Оплачено",IF(AND($E9>0,TODAY()>$B9),"◐ Частично, просрочено",IF($E9>0,"◐ Частично",IF(TODAY()>$B9,"⚠ Просрочено","⏳ Ожидается"))))))
A10: =IF(OR(Главная!$B$7="",5>IFERROR(Главная!$E$7,0)),"",DATE(YEAR(EDATE(Главная!$B$7,4)),MONTH(EDATE(Главная!$B$7,4)),1)) | B10: =IF($A10="","",MIN($A10+MAX(1,IFERROR(Главная!$B$10,1))-1,EOMONTH($A10,0))) | C10: =IF($A10="","",IF(_xlfn.MAXIFS(J_DATE,J_PER,$A10,J_CAT,"Аренда")=0,"",_xlfn.MAXIFS(J_DATE,J_PER,$A10,J_CAT,"Аренда"))) | D10: =IF($A10="","",IF(AND(5<=IFERROR(Главная!$E$7,0),$A10<=TODAY()),IFERROR(Главная!$B$9,0),0)) | E10: =IF($A10="","",SUMIFS(J_SUM,J_PER,$A10,J_CAT,"Аренда")) | F10: =IF($A10="","",$D10-$E10) | G10: =IF($A10="","",IF($D10=0,IF($E10>0,"✔ Оплачено авансом","⏳ Ожидается"),IF($E10>=$D10,"✔ Оплачено",IF(AND($E10>0,TODAY()>$B10),"◐ Частично, просрочено",IF($E10>0,"◐ Частично",IF(TODAY()>$B10,"⚠ Просрочено","⏳ Ожидается"))))))
A11: =IF(OR(Главная!$B$7="",6>IFERROR(Главная!$E$7,0)),"",DATE(YEAR(EDATE(Главная!$B$7,5)),MONTH(EDATE(Главная!$B$7,5)),1)) | B11: =IF($A11="","",MIN($A11+MAX(1,IFERROR(Главная!$B$10,1))-1,EOMONTH($A11,0))) | C11: =IF($A11="","",IF(_xlfn.MAXIFS(J_DATE,J_PER,$A11,J_CAT,"Аренда")=0,"",_xlfn.MAXIFS(J_DATE,J_PER,$A11,J_CAT,"Аренда"))) | D11: =IF($A11="","",IF(AND(6<=IFERROR(Главная!$E$7,0),$A11<=TODAY()),IFERROR(Главная!$B$9,0),0)) | E11: =IF($A11="","",SUMIFS(J_SUM,J_PER,$A11,J_CAT,"Аренда")) | F11: =IF($A11="","",$D11-$E11) | G11: =IF($A11="","",IF($D11=0,IF($E11>0,"✔ Оплачено авансом","⏳ Ожидается"),IF($E11>=$D11,"✔ Оплачено",IF(AND($E11>0,TODAY()>$B11),"◐ Частично, просрочено",IF($E11>0,"◐ Частично",IF(TODAY()>$B11,"⚠ Просрочено","⏳ Ожидается"))))))
A12: =IF(OR(Главная!$B$7="",7>IFERROR(Главная!$E$7,0)),"",DATE(YEAR(EDATE(Главная!$B$7,6)),MONTH(EDATE(Главная!$B$7,6)),1)) | B12: =IF($A12="","",MIN($A12+MAX(1,IFERROR(Главная!$B$10,1))-1,EOMONTH($A12,0))) | C12: =IF($A12="","",IF(_xlfn.MAXIFS(J_DATE,J_PER,$A12,J_CAT,"Аренда")=0,"",_xlfn.MAXIFS(J_DATE,J_PER,$A12,J_CAT,"Аренда"))) | D12: =IF($A12="","",IF(AND(7<=IFERROR(Главная!$E$7,0),$A12<=TODAY()),IFERROR(Главная!$B$9,0),0)) | E12: =IF($A12="","",SUMIFS(J_SUM,J_PER,$A12,J_CAT,"Аренда")) | F12: =IF($A12="","",$D12-$E12) | G12: =IF($A12="","",IF($D12=0,IF($E12>0,"✔ Оплачено авансом","⏳ Ожидается"),IF($E12>=$D12,"✔ Оплачено",IF(AND($E12>0,TODAY()>$B12),"◐ Частично, просрочено",IF($E12>0,"◐ Частично",IF(TODAY()>$B12,"⚠ Просрочено","⏳ Ожидается"))))))
A13: =IF(OR(Главная!$B$7="",8>IFERROR(Главная!$E$7,0)),"",DATE(YEAR(EDATE(Главная!$B$7,7)),MONTH(EDATE(Главная!$B$7,7)),1)) | B13: =IF($A13="","",MIN($A13+MAX(1,IFERROR(Главная!$B$10,1))-1,EOMONTH($A13,0))) | C13: =IF($A13="","",IF(_xlfn.MAXIFS(J_DATE,J_PER,$A13,J_CAT,"Аренда")=0,"",_xlfn.MAXIFS(J_DATE,J_PER,$A13,J_CAT,"Аренда"))) | D13: =IF($A13="","",IF(AND(8<=IFERROR(Главная!$E$7,0),$A13<=TODAY()),IFERROR(Главная!$B$9,0),0)) | E13: =IF($A13="","",SUMIFS(J_SUM,J_PER,$A13,J_CAT,"Аренда")) | F13: =IF($A13="","",$D13-$E13) | G13: =IF($A13="","",IF($D13=0,IF($E13>0,"✔ Оплачено авансом","⏳ Ожидается"),IF($E13>=$D13,"✔ Оплачено",IF(AND($E13>0,TODAY()>$B13),"◐ Частично, просрочено",IF($E13>0,"◐ Частично",IF(TODAY()>$B13,"⚠ Просрочено","⏳ Ожидается"))))))
A14: =IF(OR(Главная!$B$7="",9>IFERROR(Главная!$E$7,0)),"",DATE(YEAR(EDATE(Главная!$B$7,8)),MONTH(EDATE(Главная!$B$7,8)),1)) | B14: =IF($A14="","",MIN($A14+MAX(1,IFERROR(Главная!$B$10,1))-1,EOMONTH($A14,0))) | C14: =IF($A14="","",IF(_xlfn.MAXIFS(J_DATE,J_PER,$A14,J_CAT,"Аренда")=0,"",_xlfn.MAXIFS(J_DATE,J_PER,$A14,J_CAT,"Аренда"))) | D14: =IF($A14="","",IF(AND(9<=IFERROR(Главная!$E$7,0),$A14<=TODAY()),IFERROR(Главная!$B$9,0),0)) | E14: =IF($A14="","",SUMIFS(J_SUM,J_PER,$A14,J_CAT,"Аренда")) | F14: =IF($A14="","",$D14-$E14) | G14: =IF($A14="","",IF($D14=0,IF($E14>0,"✔ Оплачено авансом","⏳ Ожидается"),IF($E14>=$D14,"✔ Оплачено",IF(AND($E14>0,TODAY()>$B14),"◐ Частично, просрочено",IF($E14>0,"◐ Частично",IF(TODAY()>$B14,"⚠ Просрочено","⏳ Ожидается"))))))
A15: =IF(OR(Главная!$B$7="",10>IFERROR(Главная!$E$7,0)),"",DATE(YEAR(EDATE(Главная!$B$7,9)),MONTH(EDATE(Главная!$B$7,9)),1)) | B15: =IF($A15="","",MIN($A15+MAX(1,IFERROR(Главная!$B$10,1))-1,EOMONTH($A15,0))) | C15: =IF($A15="","",IF(_xlfn.MAXIFS(J_DATE,J_PER,$A15,J_CAT,"Аренда")=0,"",_xlfn.MAXIFS(J_DATE,J_PER,$A15,J_CAT,"Аренда"))) | D15: =IF($A15="","",IF(AND(10<=IFERROR(Главная!$E$7,0),$A15<=TODAY()),IFERROR(Главная!$B$9,0),0)) | E15: =IF($A15="","",SUMIFS(J_SUM,J_PER,$A15,J_CAT,"Аренда")) | F15: =IF($A15="","",$D15-$E15) | G15: =IF($A15="","",IF($D15=0,IF($E15>0,"✔ Оплачено авансом","⏳ Ожидается"),IF($E15>=$D15,"✔ Оплачено",IF(AND($E15>0,TODAY()>$B15),"◐ Частично, просрочено",IF($E15>0,"◐ Частично",IF(TODAY()>$B15,"⚠ Просрочено","⏳ Ожидается"))))))
A16: =IF(OR(Главная!$B$7="",11>IFERROR(Главная!$E$7,0)),"",DATE(YEAR(EDATE(Главная!$B$7,10)),MONTH(EDATE(Главная!$B$7,10)),1)) | B16: =IF($A16="","",MIN($A16+MAX(1,IFERROR(Главная!$B$10,1))-1,EOMONTH($A16,0))) | C16: =IF($A16="","",IF(_xlfn.MAXIFS(J_DATE,J_PER,$A16,J_CAT,"Аренда")=0,"",_xlfn.MAXIFS(J_DATE,J_PER,$A16,J_CAT,"Аренда"))) | D16: =IF($A16="","",IF(AND(11<=IFERROR(Главная!$E$7,0),$A16<=TODAY()),IFERROR(Главная!$B$9,0),0)) | E16: =IF($A16="","",SUMIFS(J_SUM,J_PER,$A16,J_CAT,"Аренда")) | F16: =IF($A16="","",$D16-$E16) | G16: =IF($A16="","",IF($D16=0,IF($E16>0,"✔ Оплачено авансом","⏳ Ожидается"),IF($E16>=$D16,"✔ Оплачено",IF(AND($E16>0,TODAY()>$B16),"◐ Частично, просрочено",IF($E16>0,"◐ Частично",IF(TODAY()>$B16,"⚠ Просрочено","⏳ Ожидается"))))))
A17: =IF(OR(Главная!$B$7="",12>IFERROR(Главная!$E$7,0)),"",DATE(YEAR(EDATE(Главная!$B$7,11)),MONTH(EDATE(Главная!$B$7,11)),1)) | B17: =IF($A17="","",MIN($A17+MAX(1,IFERROR(Главная!$B$10,1))-1,EOMONTH($A17,0))) | C17: =IF($A17="","",IF(_xlfn.MAXIFS(J_DATE,J_PER,$A17,J_CAT,"Аренда")=0,"",_xlfn.MAXIFS(J_DATE,J_PER,$A17,J_CAT,"Аренда"))) | D17: =IF($A17="","",IF(AND(12<=IFERROR(Главная!$E$7,0),$A17<=TODAY()),IFERROR(Главная!$B$9,0),0)) | E17: =IF($A17="","",SUMIFS(J_SUM,J_PER,$A17,J_CAT,"Аренда")) | F17: =IF($A17="","",$D17-$E17) | G17: =IF($A17="","",IF($D17=0,IF($E17>0,"✔ Оплачено авансом","⏳ Ожидается"),IF($E17>=$D17,"✔ Оплачено",IF(AND($E17>0,TODAY()>$B17),"◐ Частично, просрочено",IF($E17>0,"◐ Частично",IF(TODAY()>$B17,"⚠ Просрочено","⏳ Ожидается"))))))
A18: =IF(OR(Главная!$B$7="",13>IFERROR(Главная!$E$7,0)),"",DATE(YEAR(EDATE(Главная!$B$7,12)),MONTH(EDATE(Главная!$B$7,12)),1)) | B18: =IF($A18="","",MIN($A18+MAX(1,IFERROR(Главная!$B$10,1))-1,EOMONTH($A18,0))) | C18: =IF($A18="","",IF(_xlfn.MAXIFS(J_DATE,J_PER,$A18,J_CAT,"Аренда")=0,"",_xlfn.MAXIFS(J_DATE,J_PER,$A18,J_CAT,"Аренда"))) | D18: =IF($A18="","",IF(AND(13<=IFERROR(Главная!$E$7,0),$A18<=TODAY()),IFERROR(Главная!$B$9,0),0)) | E18: =IF($A18="","",SUMIFS(J_SUM,J_PER,$A18,J_CAT,"Аренда")) | F18: =IF($A18="","",$D18-$E18) | G18: =IF($A18="","",IF($D18=0,IF($E18>0,"✔ Оплачено авансом","⏳ Ожидается"),IF($E18>=$D18,"✔ Оплачено",IF(AND($E18>0,TODAY()>$B18),"◐ Частично, просрочено",IF($E18>0,"◐ Частично",IF(TODAY()>$B18,"⚠ Просрочено","⏳ Ожидается"))))))
A19: =IF(OR(Главная!$B$7="",14>IFERROR(Главная!$E$7,0)),"",DATE(YEAR(EDATE(Главная!$B$7,13)),MONTH(EDATE(Главная!$B$7,13)),1)) | B19: =IF($A19="","",MIN($A19+MAX(1,IFERROR(Главная!$B$10,1))-1,EOMONTH($A19,0))) | C19: =IF($A19="","",IF(_xlfn.MAXIFS(J_DATE,J_PER,$A19,J_CAT,"Аренда")=0,"",_xlfn.MAXIFS(J_DATE,J_PER,$A19,J_CAT,"Аренда"))) | D19: =IF($A19="","",IF(AND(14<=IFERROR(Главная!$E$7,0),$A19<=TODAY()),IFERROR(Главная!$B$9,0),0)) | E19: =IF($A19="","",SUMIFS(J_SUM,J_PER,$A19,J_CAT,"Аренда")) | F19: =IF($A19="","",$D19-$E19) | G19: =IF($A19="","",IF($D19=0,IF($E19>0,"✔ Оплачено авансом","⏳ Ожидается"),IF($E19>=$D19,"✔ Оплачено",IF(AND($E19>0,TODAY()>$B19),"◐ Частично, просрочено",IF($E19>0,"◐ Частично",IF(TODAY()>$B19,"⚠ Просрочено","⏳ Ожидается"))))))
A20: =IF(OR(Главная!$B$7="",15>IFERROR(Главная!$E$7,0)),"",DATE(YEAR(EDATE(Главная!$B$7,14)),MONTH(EDATE(Главная!$B$7,14)),1)) | B20: =IF($A20="","",MIN($A20+MAX(1,IFERROR(Главная!$B$10,1))-1,EOMONTH($A20,0))) | C20: =IF($A20="","",IF(_xlfn.MAXIFS(J_DATE,J_PER,$A20,J_CAT,"Аренда")=0,"",_xlfn.MAXIFS(J_DATE,J_PER,$A20,J_CAT,"Аренда"))) | D20: =IF($A20="","",IF(AND(15<=IFERROR(Главная!$E$7,0),$A20<=TODAY()),IFERROR(Главная!$B$9,0),0)) | E20: =IF($A20="","",SUMIFS(J_SUM,J_PER,$A20,J_CAT,"Аренда")) | F20: =IF($A20="","",$D20-$E20) | G20: =IF($A20="","",IF($D20=0,IF($E20>0,"✔ Оплачено авансом","⏳ Ожидается"),IF($E20>=$D20,"✔ Оплачено",IF(AND($E20>0,TODAY()>$B20),"◐ Частично, просрочено",IF($E20>0,"◐ Частично",IF(TODAY()>$B20,"⚠ Просрочено","⏳ Ожидается"))))))
A21: =IF(OR(Главная!$B$7="",16>IFERROR(Главная!$E$7,0)),"",DATE(YEAR(EDATE(Главная!$B$7,15)),MONTH(EDATE(Главная!$B$7,15)),1)) | B21: =IF($A21="","",MIN($A21+MAX(1,IFERROR(Главная!$B$10,1))-1,EOMONTH($A21,0))) | C21: =IF($A21="","",IF(_xlfn.MAXIFS(J_DATE,J_PER,$A21,J_CAT,"Аренда")=0,"",_xlfn.MAXIFS(J_DATE,J_PER,$A21,J_CAT,"Аренда"))) | D21: =IF($A21="","",IF(AND(16<=IFERROR(Главная!$E$7,0),$A21<=TODAY()),IFERROR(Главная!$B$9,0),0)) | E21: =IF($A21="","",SUMIFS(J_SUM,J_PER,$A21,J_CAT,"Аренда")) | F21: =IF($A21="","",$D21-$E21) | G21: =IF($A21="","",IF($D21=0,IF($E21>0,"✔ Оплачено авансом","⏳ Ожидается"),IF($E21>=$D21,"✔ Оплачено",IF(AND($E21>0,TODAY()>$B21),"◐ Частично, просрочено",IF($E21>0,"◐ Частично",IF(TODAY()>$B21,"⚠ Просрочено","⏳ Ожидается"))))))
A22: =IF(OR(Главная!$B$7="",17>IFERROR(Главная!$E$7,0)),"",DATE(YEAR(EDATE(Главная!$B$7,16)),MONTH(EDATE(Главная!$B$7,16)),1)) | B22: =IF($A22="","",MIN($A22+MAX(1,IFERROR(Главная!$B$10,1))-1,EOMONTH($A22,0))) | C22: =IF($A22="","",IF(_xlfn.MAXIFS(J_DATE,J_PER,$A22,J_CAT,"Аренда")=0,"",_xlfn.MAXIFS(J_DATE,J_PER,$A22,J_CAT,"Аренда"))) | D22: =IF($A22="","",IF(AND(17<=IFERROR(Главная!$E$7,0),$A22<=TODAY()),IFERROR(Главная!$B$9,0),0)) | E22: =IF($A22="","",SUMIFS(J_SUM,J_PER,$A22,J_CAT,"Аренда")) | F22: =IF($A22="","",$D22-$E22) | G22: =IF($A22="","",IF($D22=0,IF($E22>0,"✔ Оплачено авансом","⏳ Ожидается"),IF($E22>=$D22,"✔ Оплачено",IF(AND($E22>0,TODAY()>$B22),"◐ Частично, просрочено",IF($E22>0,"◐ Частично",IF(TODAY()>$B22,"⚠ Просрочено","⏳ Ожидается"))))))
A23: =IF(OR(Главная!$B$7="",18>IFERROR(Главная!$E$7,0)),"",DATE(YEAR(EDATE(Главная!$B$7,17)),MONTH(EDATE(Главная!$B$7,17)),1)) | B23: =IF($A23="","",MIN($A23+MAX(1,IFERROR(Главная!$B$10,1))-1,EOMONTH($A23,0))) | C23: =IF($A23="","",IF(_xlfn.MAXIFS(J_DATE,J_PER,$A23,J_CAT,"Аренда")=0,"",_xlfn.MAXIFS(J_DATE,J_PER,$A23,J_CAT,"Аренда"))) | D23: =IF($A23="","",IF(AND(18<=IFERROR(Главная!$E$7,0),$A23<=TODAY()),IFERROR(Главная!$B$9,0),0)) | E23: =IF($A23="","",SUMIFS(J_SUM,J_PER,$A23,J_CAT,"Аренда")) | F23: =IF($A23="","",$D23-$E23) | G23: =IF($A23="","",IF($D23=0,IF($E23>0,"✔ Оплачено авансом","⏳ Ожидается"),IF($E23>=$D23,"✔ Оплачено",IF(AND($E23>0,TODAY()>$B23),"◐ Частично, просрочено",IF($E23>0,"◐ Частично",IF(TODAY()>$B23,"⚠ Просрочено","⏳ Ожидается"))))))
A24: =IF(OR(Главная!$B$7="",19>IFERROR(Главная!$E$7,0)),"",DATE(YEAR(EDATE(Главная!$B$7,18)),MONTH(EDATE(Главная!$B$7,18)),1)) | B24: =IF($A24="","",MIN($A24+MAX(1,IFERROR(Главная!$B$10,1))-1,EOMONTH($A24,0))) | C24: =IF($A24="","",IF(_xlfn.MAXIFS(J_DATE,J_PER,$A24,J_CAT,"Аренда")=0,"",_xlfn.MAXIFS(J_DATE,J_PER,$A24,J_CAT,"Аренда"))) | D24: =IF($A24="","",IF(AND(19<=IFERROR(Главная!$E$7,0),$A24<=TODAY()),IFERROR(Главная!$B$9,0),0)) | E24: =IF($A24="","",SUMIFS(J_SUM,J_PER,$A24,J_CAT,"Аренда")) | F24: =IF($A24="","",$D24-$E24) | G24: =IF($A24="","",IF($D24=0,IF($E24>0,"✔ Оплачено авансом","⏳ Ожидается"),IF($E24>=$D24,"✔ Оплачено",IF(AND($E24>0,TODAY()>$B24),"◐ Частично, просрочено",IF($E24>0,"◐ Частично",IF(TODAY()>$B24,"⚠ Просрочено","⏳ Ожидается"))))))
A25: =IF(OR(Главная!$B$7="",20>IFERROR(Главная!$E$7,0)),"",DATE(YEAR(EDATE(Главная!$B$7,19)),MONTH(EDATE(Главная!$B$7,19)),1)) | B25: =IF($A25="","",MIN($A25+MAX(1,IFERROR(Главная!$B$10,1))-1,EOMONTH($A25,0))) | C25: =IF($A25="","",IF(_xlfn.MAXIFS(J_DATE,J_PER,$A25,J_CAT,"Аренда")=0,"",_xlfn.MAXIFS(J_DATE,J_PER,$A25,J_CAT,"Аренда"))) | D25: =IF($A25="","",IF(AND(20<=IFERROR(Главная!$E$7,0),$A25<=TODAY()),IFERROR(Главная!$B$9,0),0)) | E25: =IF($A25="","",SUMIFS(J_SUM,J_PER,$A25,J_CAT,"Аренда")) | F25: =IF($A25="","",$D25-$E25) | G25: =IF($A25="","",IF($D25=0,IF($E25>0,"✔ Оплачено авансом","⏳ Ожидается"),IF($E25>=$D25,"✔ Оплачено",IF(AND($E25>0,TODAY()>$B25),"◐ Частично, просрочено",IF($E25>0,"◐ Частично",IF(TODAY()>$B25,"⚠ Просрочено","⏳ Ожидается"))))))
A26: =IF(OR(Главная!$B$7="",21>IFERROR(Главная!$E$7,0)),"",DATE(YEAR(EDATE(Главная!$B$7,20)),MONTH(EDATE(Главная!$B$7,20)),1)) | B26: =IF($A26="","",MIN($A26+MAX(1,IFERROR(Главная!$B$10,1))-1,EOMONTH($A26,0))) | C26: =IF($A26="","",IF(_xlfn.MAXIFS(J_DATE,J_PER,$A26,J_CAT,"Аренда")=0,"",_xlfn.MAXIFS(J_DATE,J_PER,$A26,J_CAT,"Аренда"))) | D26: =IF($A26="","",IF(AND(21<=IFERROR(Главная!$E$7,0),$A26<=TODAY()),IFERROR(Главная!$B$9,0),0)) | E26: =IF($A26="","",SUMIFS(J_SUM,J_PER,$A26,J_CAT,"Аренда")) | F26: =IF($A26="","",$D26-$E26) | G26: =IF($A26="","",IF($D26=0,IF($E26>0,"✔ Оплачено авансом","⏳ Ожидается"),IF($E26>=$D26,"✔ Оплачено",IF(AND($E26>0,TODAY()>$B26),"◐ Частично, просрочено",IF($E26>0,"◐ Частично",IF(TODAY()>$B26,"⚠ Просрочено","⏳ Ожидается"))))))
A27: =IF(OR(Главная!$B$7="",22>IFERROR(Главная!$E$7,0)),"",DATE(YEAR(EDATE(Главная!$B$7,21)),MONTH(EDATE(Главная!$B$7,21)),1)) | B27: =IF($A27="","",MIN($A27+MAX(1,IFERROR(Главная!$B$10,1))-1,EOMONTH($A27,0))) | C27: =IF($A27="","",IF(_xlfn.MAXIFS(J_DATE,J_PER,$A27,J_CAT,"Аренда")=0,"",_xlfn.MAXIFS(J_DATE,J_PER,$A27,J_CAT,"Аренда"))) | D27: =IF($A27="","",IF(AND(22<=IFERROR(Главная!$E$7,0),$A27<=TODAY()),IFERROR(Главная!$B$9,0),0)) | E27: =IF($A27="","",SUMIFS(J_SUM,J_PER,$A27,J_CAT,"Аренда")) | F27: =IF($A27="","",$D27-$E27) | G27: =IF($A27="","",IF($D27=0,IF($E27>0,"✔ Оплачено авансом","⏳ Ожидается"),IF($E27>=$D27,"✔ Оплачено",IF(AND($E27>0,TODAY()>$B27),"◐ Частично, просрочено",IF($E27>0,"◐ Частично",IF(TODAY()>$B27,"⚠ Просрочено","⏳ Ожидается"))))))
A28: =IF(OR(Главная!$B$7="",23>IFERROR(Главная!$E$7,0)),"",DATE(YEAR(EDATE(Главная!$B$7,22)),MONTH(EDATE(Главная!$B$7,22)),1)) | B28: =IF($A28="","",MIN($A28+MAX(1,IFERROR(Главная!$B$10,1))-1,EOMONTH($A28,0))) | C28: =IF($A28="","",IF(_xlfn.MAXIFS(J_DATE,J_PER,$A28,J_CAT,"Аренда")=0,"",_xlfn.MAXIFS(J_DATE,J_PER,$A28,J_CAT,"Аренда"))) | D28: =IF($A28="","",IF(AND(23<=IFERROR(Главная!$E$7,0),$A28<=TODAY()),IFERROR(Главная!$B$9,0),0)) | E28: =IF($A28="","",SUMIFS(J_SUM,J_PER,$A28,J_CAT,"Аренда")) | F28: =IF($A28="","",$D28-$E28) | G28: =IF($A28="","",IF($D28=0,IF($E28>0,"✔ Оплачено авансом","⏳ Ожидается"),IF($E28>=$D28,"✔ Оплачено",IF(AND($E28>0,TODAY()>$B28),"◐ Частично, просрочено",IF($E28>0,"◐ Частично",IF(TODAY()>$B28,"⚠ Просрочено","⏳ Ожидается"))))))
A29: =IF(OR(Главная!$B$7="",24>IFERROR(Главная!$E$7,0)),"",DATE(YEAR(EDATE(Главная!$B$7,23)),MONTH(EDATE(Главная!$B$7,23)),1)) | B29: =IF($A29="","",MIN($A29+MAX(1,IFERROR(Главная!$B$10,1))-1,EOMONTH($A29,0))) | C29: =IF($A29="","",IF(_xlfn.MAXIFS(J_DATE,J_PER,$A29,J_CAT,"Аренда")=0,"",_xlfn.MAXIFS(J_DATE,J_PER,$A29,J_CAT,"Аренда"))) | D29: =IF($A29="","",IF(AND(24<=IFERROR(Главная!$E$7,0),$A29<=TODAY()),IFERROR(Главная!$B$9,0),0)) | E29: =IF($A29="","",SUMIFS(J_SUM,J_PER,$A29,J_CAT,"Аренда")) | F29: =IF($A29="","",$D29-$E29) | G29: =IF($A29="","",IF($D29=0,IF($E29>0,"✔ Оплачено авансом","⏳ Ожидается"),IF($E29>=$D29,"✔ Оплачено",IF(AND($E29>0,TODAY()>$B29),"◐ Частично, просрочено",IF($E29>0,"◐ Частично",IF(TODAY()>$B29,"⚠ Просрочено","⏳ Ожидается"))))))
A30: =IF(OR(Главная!$B$7="",25>IFERROR(Главная!$E$7,0)),"",DATE(YEAR(EDATE(Главная!$B$7,24)),MONTH(EDATE(Главная!$B$7,24)),1)) | B30: =IF($A30="","",MIN($A30+MAX(1,IFERROR(Главная!$B$10,1))-1,EOMONTH($A30,0))) | C30: =IF($A30="","",IF(_xlfn.MAXIFS(J_DATE,J_PER,$A30,J_CAT,"Аренда")=0,"",_xlfn.MAXIFS(J_DATE,J_PER,$A30,J_CAT,"Аренда"))) | D30: =IF($A30="","",IF(AND(25<=IFERROR(Главная!$E$7,0),$A30<=TODAY()),IFERROR(Главная!$B$9,0),0)) | E30: =IF($A30="","",SUMIFS(J_SUM,J_PER,$A30,J_CAT,"Аренда")) | F30: =IF($A30="","",$D30-$E30) | G30: =IF($A30="","",IF($D30=0,IF($E30>0,"✔ Оплачено авансом","⏳ Ожидается"),IF($E30>=$D30,"✔ Оплачено",IF(AND($E30>0,TODAY()>$B30),"◐ Частично, просрочено",IF($E30>0,"◐ Частично",IF(TODAY()>$B30,"⚠ Просрочено","⏳ Ожидается"))))))
A31: =IF(OR(Главная!$B$7="",26>IFERROR(Главная!$E$7,0)),"",DATE(YEAR(EDATE(Главная!$B$7,25)),MONTH(EDATE(Главная!$B$7,25)),1)) | B31: =IF($A31="","",MIN($A31+MAX(1,IFERROR(Главная!$B$10,1))-1,EOMONTH($A31,0))) | C31: =IF($A31="","",IF(_xlfn.MAXIFS(J_DATE,J_PER,$A31,J_CAT,"Аренда")=0,"",_xlfn.MAXIFS(J_DATE,J_PER,$A31,J_CAT,"Аренда"))) | D31: =IF($A31="","",IF(AND(26<=IFERROR(Главная!$E$7,0),$A31<=TODAY()),IFERROR(Главная!$B$9,0),0)) | E31: =IF($A31="","",SUMIFS(J_SUM,J_PER,$A31,J_CAT,"Аренда")) | F31: =IF($A31="","",$D31-$E31) | G31: =IF($A31="","",IF($D31=0,IF($E31>0,"✔ Оплачено авансом","⏳ Ожидается"),IF($E31>=$D31,"✔ Оплачено",IF(AND($E31>0,TODAY()>$B31),"◐ Частично, просрочено",IF($E31>0,"◐ Частично",IF(TODAY()>$B31,"⚠ Просрочено","⏳ Ожидается"))))))
A32: =IF(OR(Главная!$B$7="",27>IFERROR(Главная!$E$7,0)),"",DATE(YEAR(EDATE(Главная!$B$7,26)),MONTH(EDATE(Главная!$B$7,26)),1)) | B32: =IF($A32="","",MIN($A32+MAX(1,IFERROR(Главная!$B$10,1))-1,EOMONTH($A32,0))) | C32: =IF($A32="","",IF(_xlfn.MAXIFS(J_DATE,J_PER,$A32,J_CAT,"Аренда")=0,"",_xlfn.MAXIFS(J_DATE,J_PER,$A32,J_CAT,"Аренда"))) | D32: =IF($A32="","",IF(AND(27<=IFERROR(Главная!$E$7,0),$A32<=TODAY()),IFERROR(Главная!$B$9,0),0)) | E32: =IF($A32="","",SUMIFS(J_SUM,J_PER,$A32,J_CAT,"Аренда")) | F32: =IF($A32="","",$D32-$E32) | G32: =IF($A32="","",IF($D32=0,IF($E32>0,"✔ Оплачено авансом","⏳ Ожидается"),IF($E32>=$D32,"✔ Оплачено",IF(AND($E32>0,TODAY()>$B32),"◐ Частично, просрочено",IF($E32>0,"◐ Частично",IF(TODAY()>$B32,"⚠ Просрочено","⏳ Ожидается"))))))
A33: =IF(OR(Главная!$B$7="",28>IFERROR(Главная!$E$7,0)),"",DATE(YEAR(EDATE(Главная!$B$7,27)),MONTH(EDATE(Главная!$B$7,27)),1)) | B33: =IF($A33="","",MIN($A33+MAX(1,IFERROR(Главная!$B$10,1))-1,EOMONTH($A33,0))) | C33: =IF($A33="","",IF(_xlfn.MAXIFS(J_DATE,J_PER,$A33,J_CAT,"Аренда")=0,"",_xlfn.MAXIFS(J_DATE,J_PER,$A33,J_CAT,"Аренда"))) | D33: =IF($A33="","",IF(AND(28<=IFERROR(Главная!$E$7,0),$A33<=TODAY()),IFERROR(Главная!$B$9,0),0)) | E33: =IF($A33="","",SUMIFS(J_SUM,J_PER,$A33,J_CAT,"Аренда")) | F33: =IF($A33="","",$D33-$E33) | G33: =IF($A33="","",IF($D33=0,IF($E33>0,"✔ Оплачено авансом","⏳ Ожидается"),IF($E33>=$D33,"✔ Оплачено",IF(AND($E33>0,TODAY()>$B33),"◐ Частично, просрочено",IF($E33>0,"◐ Частично",IF(TODAY()>$B33,"⚠ Просрочено","⏳ Ожидается"))))))
A34: =IF(OR(Главная!$B$7="",29>IFERROR(Главная!$E$7,0)),"",DATE(YEAR(EDATE(Главная!$B$7,28)),MONTH(EDATE(Главная!$B$7,28)),1)) | B34: =IF($A34="","",MIN($A34+MAX(1,IFERROR(Главная!$B$10,1))-1,EOMONTH($A34,0))) | C34: =IF($A34="","",IF(_xlfn.MAXIFS(J_DATE,J_PER,$A34,J_CAT,"Аренда")=0,"",_xlfn.MAXIFS(J_DATE,J_PER,$A34,J_CAT,"Аренда"))) | D34: =IF($A34="","",IF(AND(29<=IFERROR(Главная!$E$7,0),$A34<=TODAY()),IFERROR(Главная!$B$9,0),0)) | E34: =IF($A34="","",SUMIFS(J_SUM,J_PER,$A34,J_CAT,"Аренда")) | F34: =IF($A34="","",$D34-$E34) | G34: =IF($A34="","",IF($D34=0,IF($E34>0,"✔ Оплачено авансом","⏳ Ожидается"),IF($E34>=$D34,"✔ Оплачено",IF(AND($E34>0,TODAY()>$B34),"◐ Частично, просрочено",IF($E34>0,"◐ Частично",IF(TODAY()>$B34,"⚠ Просрочено","⏳ Ожидается"))))))
A35: =IF(OR(Главная!$B$7="",30>IFERROR(Главная!$E$7,0)),"",DATE(YEAR(EDATE(Главная!$B$7,29)),MONTH(EDATE(Главная!$B$7,29)),1)) | B35: =IF($A35="","",MIN($A35+MAX(1,IFERROR(Главная!$B$10,1))-1,EOMONTH($A35,0))) | C35: =IF($A35="","",IF(_xlfn.MAXIFS(J_DATE,J_PER,$A35,J_CAT,"Аренда")=0,"",_xlfn.MAXIFS(J_DATE,J_PER,$A35,J_CAT,"Аренда"))) | D35: =IF($A35="","",IF(AND(30<=IFERROR(Главная!$E$7,0),$A35<=TODAY()),IFERROR(Главная!$B$9,0),0)) | E35: =IF($A35="","",SUMIFS(J_SUM,J_PER,$A35,J_CAT,"Аренда")) | F35: =IF($A35="","",$D35-$E35) | G35: =IF($A35="","",IF($D35=0,IF($E35>0,"✔ Оплачено авансом","⏳ Ожидается"),IF($E35>=$D35,"✔ Оплачено",IF(AND($E35>0,TODAY()>$B35),"◐ Частично, просрочено",IF($E35>0,"◐ Частично",IF(TODAY()>$B35,"⚠ Просрочено","⏳ Ожидается"))))))
A36: =IF(OR(Главная!$B$7="",31>IFERROR(Главная!$E$7,0)),"",DATE(YEAR(EDATE(Главная!$B$7,30)),MONTH(EDATE(Главная!$B$7,30)),1)) | B36: =IF($A36="","",MIN($A36+MAX(1,IFERROR(Главная!$B$10,1))-1,EOMONTH($A36,0))) | C36: =IF($A36="","",IF(_xlfn.MAXIFS(J_DATE,J_PER,$A36,J_CAT,"Аренда")=0,"",_xlfn.MAXIFS(J_DATE,J_PER,$A36,J_CAT,"Аренда"))) | D36: =IF($A36="","",IF(AND(31<=IFERROR(Главная!$E$7,0),$A36<=TODAY()),IFERROR(Главная!$B$9,0),0)) | E36: =IF($A36="","",SUMIFS(J_SUM,J_PER,$A36,J_CAT,"Аренда")) | F36: =IF($A36="","",$D36-$E36) | G36: =IF($A36="","",IF($D36=0,IF($E36>0,"✔ Оплачено авансом","⏳ Ожидается"),IF($E36>=$D36,"✔ Оплачено",IF(AND($E36>0,TODAY()>$B36),"◐ Частично, просрочено",IF($E36>0,"◐ Частично",IF(TODAY()>$B36,"⚠ Просрочено","⏳ Ожидается"))))))
A37: =IF(OR(Главная!$B$7="",32>IFERROR(Главная!$E$7,0)),"",DATE(YEAR(EDATE(Главная!$B$7,31)),MONTH(EDATE(Главная!$B$7,31)),1)) | B37: =IF($A37="","",MIN($A37+MAX(1,IFERROR(Главная!$B$10,1))-1,EOMONTH($A37,0))) | C37: =IF($A37="","",IF(_xlfn.MAXIFS(J_DATE,J_PER,$A37,J_CAT,"Аренда")=0,"",_xlfn.MAXIFS(J_DATE,J_PER,$A37,J_CAT,"Аренда"))) | D37: =IF($A37="","",IF(AND(32<=IFERROR(Главная!$E$7,0),$A37<=TODAY()),IFERROR(Главная!$B$9,0),0)) | E37: =IF($A37="","",SUMIFS(J_SUM,J_PER,$A37,J_CAT,"Аренда")) | F37: =IF($A37="","",$D37-$E37) | G37: =IF($A37="","",IF($D37=0,IF($E37>0,"✔ Оплачено авансом","⏳ Ожидается"),IF($E37>=$D37,"✔ Оплачено",IF(AND($E37>0,TODAY()>$B37),"◐ Частично, просрочено",IF($E37>0,"◐ Частично",IF(TODAY()>$B37,"⚠ Просрочено","⏳ Ожидается"))))))
A38: =IF(OR(Главная!$B$7="",33>IFERROR(Главная!$E$7,0)),"",DATE(YEAR(EDATE(Главная!$B$7,32)),MONTH(EDATE(Главная!$B$7,32)),1)) | B38: =IF($A38="","",MIN($A38+MAX(1,IFERROR(Главная!$B$10,1))-1,EOMONTH($A38,0))) | C38: =IF($A38="","",IF(_xlfn.MAXIFS(J_DATE,J_PER,$A38,J_CAT,"Аренда")=0,"",_xlfn.MAXIFS(J_DATE,J_PER,$A38,J_CAT,"Аренда"))) | D38: =IF($A38="","",IF(AND(33<=IFERROR(Главная!$E$7,0),$A38<=TODAY()),IFERROR(Главная!$B$9,0),0)) | E38: =IF($A38="","",SUMIFS(J_SUM,J_PER,$A38,J_CAT,"Аренда")) | F38: =IF($A38="","",$D38-$E38) | G38: =IF($A38="","",IF($D38=0,IF($E38>0,"✔ Оплачено авансом","⏳ Ожидается"),IF($E38>=$D38,"✔ Оплачено",IF(AND($E38>0,TODAY()>$B38),"◐ Частично, просрочено",IF($E38>0,"◐ Частично",IF(TODAY()>$B38,"⚠ Просрочено","⏳ Ожидается"))))))
A39: =IF(OR(Главная!$B$7="",34>IFERROR(Главная!$E$7,0)),"",DATE(YEAR(EDATE(Главная!$B$7,33)),MONTH(EDATE(Главная!$B$7,33)),1)) | B39: =IF($A39="","",MIN($A39+MAX(1,IFERROR(Главная!$B$10,1))-1,EOMONTH($A39,0))) | C39: =IF($A39="","",IF(_xlfn.MAXIFS(J_DATE,J_PER,$A39,J_CAT,"Аренда")=0,"",_xlfn.MAXIFS(J_DATE,J_PER,$A39,J_CAT,"Аренда"))) | D39: =IF($A39="","",IF(AND(34<=IFERROR(Главная!$E$7,0),$A39<=TODAY()),IFERROR(Главная!$B$9,0),0)) | E39: =IF($A39="","",SUMIFS(J_SUM,J_PER,$A39,J_CAT,"Аренда")) | F39: =IF($A39="","",$D39-$E39) | G39: =IF($A39="","",IF($D39=0,IF($E39>0,"✔ Оплачено авансом","⏳ Ожидается"),IF($E39>=$D39,"✔ Оплачено",IF(AND($E39>0,TODAY()>$B39),"◐ Частично, просрочено",IF($E39>0,"◐ Частично",IF(TODAY()>$B39,"⚠ Просрочено","⏳ Ожидается"))))))
A40: =IF(OR(Главная!$B$7="",35>IFERROR(Главная!$E$7,0)),"",DATE(YEAR(EDATE(Главная!$B$7,34)),MONTH(EDATE(Главная!$B$7,34)),1)) | B40: =IF($A40="","",MIN($A40+MAX(1,IFERROR(Главная!$B$10,1))-1,EOMONTH($A40,0))) | C40: =IF($A40="","",IF(_xlfn.MAXIFS(J_DATE,J_PER,$A40,J_CAT,"Аренда")=0,"",_xlfn.MAXIFS(J_DATE,J_PER,$A40,J_CAT,"Аренда"))) | D40: =IF($A40="","",IF(AND(35<=IFERROR(Главная!$E$7,0),$A40<=TODAY()),IFERROR(Главная!$B$9,0),0)) | E40: =IF($A40="","",SUMIFS(J_SUM,J_PER,$A40,J_CAT,"Аренда")) | F40: =IF($A40="","",$D40-$E40) | G40: =IF($A40="","",IF($D40=0,IF($E40>0,"✔ Оплачено авансом","⏳ Ожидается"),IF($E40>=$D40,"✔ Оплачено",IF(AND($E40>0,TODAY()>$B40),"◐ Частично, просрочено",IF($E40>0,"◐ Частично",IF(TODAY()>$B40,"⚠ Просрочено","⏳ Ожидается"))))))
A41: =IF(OR(Главная!$B$7="",36>IFERROR(Главная!$E$7,0)),"",DATE(YEAR(EDATE(Главная!$B$7,35)),MONTH(EDATE(Главная!$B$7,35)),1)) | B41: =IF($A41="","",MIN($A41+MAX(1,IFERROR(Главная!$B$10,1))-1,EOMONTH($A41,0))) | C41: =IF($A41="","",IF(_xlfn.MAXIFS(J_DATE,J_PER,$A41,J_CAT,"Аренда")=0,"",_xlfn.MAXIFS(J_DATE,J_PER,$A41,J_CAT,"Аренда"))) | D41: =IF($A41="","",IF(AND(36<=IFERROR(Главная!$E$7,0),$A41<=TODAY()),IFERROR(Главная!$B$9,0),0)) | E41: =IF($A41="","",SUMIFS(J_SUM,J_PER,$A41,J_CAT,"Аренда")) | F41: =IF($A41="","",$D41-$E41) | G41: =IF($A41="","",IF($D41=0,IF($E41>0,"✔ Оплачено авансом","⏳ Ожидается"),IF($E41>=$D41,"✔ Оплачено",IF(AND($E41>0,TODAY()>$B41),"◐ Частично, просрочено",IF($E41>0,"◐ Частично",IF(TODAY()>$B41,"⚠ Просрочено","⏳ Ожидается"))))))
...

Sheet Аналитика
A1: АНАЛИТИКА ПЛАТЕЖЕЙ
A2: Разбивка по месяцам, годам и способам оплаты — считается автоматически
A4: ПО МЕСЯЦАМ
A5: Месяц | B5: Аренда | C5: Налоги | D5: Коммуналка | E5: Залог | F5: Прочее | G5: Итого
A7: =IF(История!$A$6="","",История!$A$6) | B7: =IF($A7="","",SUMIFS(J_SUM,J_PER,$A7,J_CAT,"Аренда")) | C7: =IF($A7="","",SUMIFS(J_SUM,J_PER,$A7,J_CAT,"Налог")) | D7: =IF($A7="","",SUMIFS(J_SUM,J_PER,$A7,J_CAT,"Коммунальные услуги")) | E7: =IF($A7="","",SUMIFS(J_SUM,J_PER,$A7,J_CAT,"Залог")) | F7: =IF($A7="","",SUMIFS(J_SUM,J_PER,$A7,J_CAT,"Прочее")) | G7: =IF($A7="","",SUM($B7:$F7))
A8: =IF(История!$A$7="","",История!$A$7) | B8: =IF($A8="","",SUMIFS(J_SUM,J_PER,$A8,J_CAT,"Аренда")) | C8: =IF($A8="","",SUMIFS(J_SUM,J_PER,$A8,J_CAT,"Налог")) | D8: =IF($A8="","",SUMIFS(J_SUM,J_PER,$A8,J_CAT,"Коммунальные услуги")) | E8: =IF($A8="","",SUMIFS(J_SUM,J_PER,$A8,J_CAT,"Залог")) | F8: =IF($A8="","",SUMIFS(J_SUM,J_PER,$A8,J_CAT,"Прочее")) | G8: =IF($A8="","",SUM($B8:$F8))
A9: =IF(История!$A$8="","",История!$A$8) | B9: =IF($A9="","",SUMIFS(J_SUM,J_PER,$A9,J_CAT,"Аренда")) | C9: =IF($A9="","",SUMIFS(J_SUM,J_PER,$A9,J_CAT,"Налог")) | D9: =IF($A9="","",SUMIFS(J_SUM,J_PER,$A9,J_CAT,"Коммунальные услуги")) | E9: =IF($A9="","",SUMIFS(J_SUM,J_PER,$A9,J_CAT,"Залог")) | F9: =IF($A9="","",SUMIFS(J_SUM,J_PER,$A9,J_CAT,"Прочее")) | G9: =IF($A9="","",SUM($B9:$F9))
A10: =IF(История!$A$9="","",История!$A$9) | B10: =IF($A10="","",SUMIFS(J_SUM,J_PER,$A10,J_CAT,"Аренда")) | C10: =IF($A10="","",SUMIFS(J_SUM,J_PER,$A10,J_CAT,"Налог")) | D10: =IF($A10="","",SUMIFS(J_SUM,J_PER,$A10,J_CAT,"Коммунальные услуги")) | E10: =IF($A10="","",SUMIFS(J_SUM,J_PER,$A10,J_CAT,"Залог")) | F10: =IF($A10="","",SUMIFS(J_SUM,J_PER,$A10,J_CAT,"Прочее")) | G10: =IF($A10="","",SUM($B10:$F10))
A11: =IF(История!$A$10="","",История!$A$10) | B11: =IF($A11="","",SUMIFS(J_SUM,J_PER,$A11,J_CAT,"Аренда")) | C11: =IF($A11="","",SUMIFS(J_SUM,J_PER,$A11,J_CAT,"Налог")) | D11: =IF($A11="","",SUMIFS(J_SUM,J_PER,$A11,J_CAT,"Коммунальные услуги")) | E11: =IF($A11="","",SUMIFS(J_SUM,J_PER,$A11,J_CAT,"Залог")) | F11: =IF($A11="","",SUMIFS(J_SUM,J_PER,$A11,J_CAT,"Прочее")) | G11: =IF($A11="","",SUM($B11:$F11))
A12: =IF(История!$A$11="","",История!$A$11) | B12: =IF($A12="","",SUMIFS(J_SUM,J_PER,$A12,J_CAT,"Аренда")) | C12: =IF($A12="","",SUMIFS(J_SUM,J_PER,$A12,J_CAT,"Налог")) | D12: =IF($A12="","",SUMIFS(J_SUM,J_PER,$A12,J_CAT,"Коммунальные услуги")) | E12: =IF($A12="","",SUMIFS(J_SUM,J_PER,$A12,J_CAT,"Залог")) | F12: =IF($A12="","",SUMIFS(J_SUM,J_PER,$A12,J_CAT,"Прочее")) | G12: =IF($A12="","",SUM($B12:$F12))
A13: =IF(История!$A$12="","",История!$A$12) | B13: =IF($A13="","",SUMIFS(J_SUM,J_PER,$A13,J_CAT,"Аренда")) | C13: =IF($A13="","",SUMIFS(J_SUM,J_PER,$A13,J_CAT,"Налог")) | D13: =IF($A13="","",SUMIFS(J_SUM,J_PER,$A13,J_CAT,"Коммунальные услуги")) | E13: =IF($A13="","",SUMIFS(J_SUM,J_PER,$A13,J_CAT,"Залог")) | F13: =IF($A13="","",SUMIFS(J_SUM,J_PER,$A13,J_CAT,"Прочее")) | G13: =IF($A13="","",SUM($B13:$F13))
A14: =IF(История!$A$13="","",История!$A$13) | B14: =IF($A14="","",SUMIFS(J_SUM,J_PER,$A14,J_CAT,"Аренда")) | C14: =IF($A14="","",SUMIFS(J_SUM,J_PER,$A14,J_CAT,"Налог")) | D14: =IF($A14="","",SUMIFS(J_SUM,J_PER,$A14,J_CAT,"Коммунальные услуги")) | E14: =IF($A14="","",SUMIFS(J_SUM,J_PER,$A14,J_CAT,"Залог")) | F14: =IF($A14="","",SUMIFS(J_SUM,J_PER,$A14,J_CAT,"Прочее")) | G14: =IF($A14="","",SUM($B14:$F14))
A15: =IF(История!$A$14="","",История!$A$14) | B15: =IF($A15="","",SUMIFS(J_SUM,J_PER,$A15,J_CAT,"Аренда")) | C15: =IF($A15="","",SUMIFS(J_SUM,J_PER,$A15,J_CAT,"Налог")) | D15: =IF($A15="","",SUMIFS(J_SUM,J_PER,$A15,J_CAT,"Коммунальные услуги")) | E15: =IF($A15="","",SUMIFS(J_SUM,J_PER,$A15,J_CAT,"Залог")) | F15: =IF($A15="","",SUMIFS(J_SUM,J_PER,$A15,J_CAT,"Прочее")) | G15: =IF($A15="","",SUM($B15:$F15))
A16: =IF(История!$A$15="","",История!$A$15) | B16: =IF($A16="","",SUMIFS(J_SUM,J_PER,$A16,J_CAT,"Аренда")) | C16: =IF($A16="","",SUMIFS(J_SUM,J_PER,$A16,J_CAT,"Налог")) | D16: =IF($A16="","",SUMIFS(J_SUM,J_PER,$A16,J_CAT,"Коммунальные услуги")) | E16: =IF($A16="","",SUMIFS(J_SUM,J_PER,$A16,J_CAT,"Залог")) | F16: =IF($A16="","",SUMIFS(J_SUM,J_PER,$A16,J_CAT,"Прочее")) | G16: =IF($A16="","",SUM($B16:$F16))
A17: =IF(История!$A$16="","",История!$A$16) | B17: =IF($A17="","",SUMIFS(J_SUM,J_PER,$A17,J_CAT,"Аренда")) | C17: =IF($A17="","",SUMIFS(J_SUM,J_PER,$A17,J_CAT,"Налог")) | D17: =IF($A17="","",SUMIFS(J_SUM,J_PER,$A17,J_CAT,"Коммунальные услуги")) | E17: =IF($A17="","",SUMIFS(J_SUM,J_PER,$A17,J_CAT,"Залог")) | F17: =IF($A17="","",SUMIFS(J_SUM,J_PER,$A17,J_CAT,"Прочее")) | G17: =IF($A17="","",SUM($B17:$F17))
A18: =IF(История!$A$17="","",История!$A$17) | B18: =IF($A18="","",SUMIFS(J_SUM,J_PER,$A18,J_CAT,"Аренда")) | C18: =IF($A18="","",SUMIFS(J_SUM,J_PER,$A18,J_CAT,"Налог")) | D18: =IF($A18="","",SUMIFS(J_SUM,J_PER,$A18,J_CAT,"Коммунальные услуги")) | E18: =IF($A18="","",SUMIFS(J_SUM,J_PER,$A18,J_CAT,"Залог")) | F18: =IF($A18="","",SUMIFS(J_SUM,J_PER,$A18,J_CAT,"Прочее")) | G18: =IF($A18="","",SUM($B18:$F18))
A19: =IF(История!$A$18="","",История!$A$18) | B19: =IF($A19="","",SUMIFS(J_SUM,J_PER,$A19,J_CAT,"Аренда")) | C19: =IF($A19="","",SUMIFS(J_SUM,J_PER,$A19,J_CAT,"Налог")) | D19: =IF($A19="","",SUMIFS(J_SUM,J_PER,$A19,J_CAT,"Коммунальные услуги")) | E19: =IF($A19="","",SUMIFS(J_SUM,J_PER,$A19,J_CAT,"Залог")) | F19: =IF($A19="","",SUMIFS(J_SUM,J_PER,$A19,J_CAT,"Прочее")) | G19: =IF($A19="","",SUM($B19:$F19))
A20: =IF(История!$A$19="","",История!$A$19) | B20: =IF($A20="","",SUMIFS(J_SUM,J_PER,$A20,J_CAT,"Аренда")) | C20: =IF($A20="","",SUMIFS(J_SUM,J_PER,$A20,J_CAT,"Налог")) | D20: =IF($A20="","",SUMIFS(J_SUM,J_PER,$A20,J_CAT,"Коммунальные услуги")) | E20: =IF($A20="","",SUMIFS(J_SUM,J_PER,$A20,J_CAT,"Залог")) | F20: =IF($A20="","",SUMIFS(J_SUM,J_PER,$A20,J_CAT,"Прочее")) | G20: =IF($A20="","",SUM($B20:$F20))
A21: =IF(История!$A$20="","",История!$A$20) | B21: =IF($A21="","",SUMIFS(J_SUM,J_PER,$A21,J_CAT,"Аренда")) | C21: =IF($A21="","",SUMIFS(J_SUM,J_PER,$A21,J_CAT,"Налог")) | D21: =IF($A21="","",SUMIFS(J_SUM,J_PER,$A21,J_CAT,"Коммунальные услуги")) | E21: =IF($A21="","",SUMIFS(J_SUM,J_PER,$A21,J_CAT,"Залог")) | F21: =IF($A21="","",SUMIFS(J_SUM,J_PER,$A21,J_CAT,"Прочее")) | G21: =IF($A21="","",SUM($B21:$F21))
A22: =IF(История!$A$21="","",История!$A$21) | B22: =IF($A22="","",SUMIFS(J_SUM,J_PER,$A22,J_CAT,"Аренда")) | C22: =IF($A22="","",SUMIFS(J_SUM,J_PER,$A22,J_CAT,"Налог")) | D22: =IF($A22="","",SUMIFS(J_SUM,J_PER,$A22,J_CAT,"Коммунальные услуги")) | E22: =IF($A22="","",SUMIFS(J_SUM,J_PER,$A22,J_CAT,"Залог")) | F22: =IF($A22="","",SUMIFS(J_SUM,J_PER,$A22,J_CAT,"Прочее")) | G22: =IF($A22="","",SUM($B22:$F22))
A23: =IF(История!$A$22="","",История!$A$22) | B23: =IF($A23="","",SUMIFS(J_SUM,J_PER,$A23,J_CAT,"Аренда")) | C23: =IF($A23="","",SUMIFS(J_SUM,J_PER,$A23,J_CAT,"Налог")) | D23: =IF($A23="","",SUMIFS(J_SUM,J_PER,$A23,J_CAT,"Коммунальные услуги")) | E23: =IF($A23="","",SUMIFS(J_SUM,J_PER,$A23,J_CAT,"Залог")) | F23: =IF($A23="","",SUMIFS(J_SUM,J_PER,$A23,J_CAT,"Прочее")) | G23: =IF($A23="","",SUM($B23:$F23))
A24: =IF(История!$A$23="","",История!$A$23) | B24: =IF($A24="","",SUMIFS(J_SUM,J_PER,$A24,J_CAT,"Аренда")) | C24: =IF($A24="","",SUMIFS(J_SUM,J_PER,$A24,J_CAT,"Налог")) | D24: =IF($A24="","",SUMIFS(J_SUM,J_PER,$A24,J_CAT,"Коммунальные услуги")) | E24: =IF($A24="","",SUMIFS(J_SUM,J_PER,$A24,J_CAT,"Залог")) | F24: =IF($A24="","",SUMIFS(J_SUM,J_PER,$A24,J_CAT,"Прочее")) | G24: =IF($A24="","",SUM($B24:$F24))
A25: =IF(История!$A$24="","",История!$A$24) | B25: =IF($A25="","",SUMIFS(J_SUM,J_PER,$A25,J_CAT,"Аренда")) | C25: =IF($A25="","",SUMIFS(J_SUM,J_PER,$A25,J_CAT,"Налог")) | D25: =IF($A25="","",SUMIFS(J_SUM,J_PER,$A25,J_CAT,"Коммунальные услуги")) | E25: =IF($A25="","",SUMIFS(J_SUM,J_PER,$A25,J_CAT,"Залог")) | F25: =IF($A25="","",SUMIFS(J_SUM,J_PER,$A25,J_CAT,"Прочее")) | G25: =IF($A25="","",SUM($B25:$F25))
A26: =IF(История!$A$25="","",История!$A$25) | B26: =IF($A26="","",SUMIFS(J_SUM,J_PER,$A26,J_CAT,"Аренда")) | C26: =IF($A26="","",SUMIFS(J_SUM,J_PER,$A26,J_CAT,"Налог")) | D26: =IF($A26="","",SUMIFS(J_SUM,J_PER,$A26,J_CAT,"Коммунальные услуги")) | E26: =IF($A26="","",SUMIFS(J_SUM,J_PER,$A26,J_CAT,"Залог")) | F26: =IF($A26="","",SUMIFS(J_SUM,J_PER,$A26,J_CAT,"Прочее")) | G26: =IF($A26="","",SUM($B26:$F26))
A27: =IF(История!$A$26="","",История!$A$26) | B27: =IF($A27="","",SUMIFS(J_SUM,J_PER,$A27,J_CAT,"Аренда")) | C27: =IF($A27="","",SUMIFS(J_SUM,J_PER,$A27,J_CAT,"Налог")) | D27: =IF($A27="","",SUMIFS(J_SUM,J_PER,$A27,J_CAT,"Коммунальные услуги")) | E27: =IF($A27="","",SUMIFS(J_SUM,J_PER,$A27,J_CAT,"Залог")) | F27: =IF($A27="","",SUMIFS(J_SUM,J_PER,$A27,J_CAT,"Прочее")) | G27: =IF($A27="","",SUM($B27:$F27))
A28: =IF(История!$A$27="","",История!$A$27) | B28: =IF($A28="","",SUMIFS(J_SUM,J_PER,$A28,J_CAT,"Аренда")) | C28: =IF($A28="","",SUMIFS(J_SUM,J_PER,$A28,J_CAT,"Налог")) | D28: =IF($A28="","",SUMIFS(J_SUM,J_PER,$A28,J_CAT,"Коммунальные услуги")) | E28: =IF($A28="","",SUMIFS(J_SUM,J_PER,$A28,J_CAT,"Залог")) | F28: =IF($A28="","",SUMIFS(J_SUM,J_PER,$A28,J_CAT,"Прочее")) | G28: =IF($A28="","",SUM($B28:$F28))
A29: =IF(История!$A$28="","",История!$A$28) | B29: =IF($A29="","",SUMIFS(J_SUM,J_PER,$A29,J_CAT,"Аренда")) | C29: =IF($A29="","",SUMIFS(J_SUM,J_PER,$A29,J_CAT,"Налог")) | D29: =IF($A29="","",SUMIFS(J_SUM,J_PER,$A29,J_CAT,"Коммунальные услуги")) | E29: =IF($A29="","",SUMIFS(J_SUM,J_PER,$A29,J_CAT,"Залог")) | F29: =IF($A29="","",SUMIFS(J_SUM,J_PER,$A29,J_CAT,"Прочее")) | G29: =IF($A29="","",SUM($B29:$F29))
A30: =IF(История!$A$29="","",История!$A$29) | B30: =IF($A30="","",SUMIFS(J_SUM,J_PER,$A30,J_CAT,"Аренда")) | C30: =IF($A30="","",SUMIFS(J_SUM,J_PER,$A30,J_CAT,"Налог")) | D30: =IF($A30="","",SUMIFS(J_SUM,J_PER,$A30,J_CAT,"Коммунальные услуги")) | E30: =IF($A30="","",SUMIFS(J_SUM,J_PER,$A30,J_CAT,"Залог")) | F30: =IF($A30="","",SUMIFS(J_SUM,J_PER,$A30,J_CAT,"Прочее")) | G30: =IF($A30="","",SUM($B30:$F30))
A31: =IF(История!$A$30="","",История!$A$30) | B31: =IF($A31="","",SUMIFS(J_SUM,J_PER,$A31,J_CAT,"Аренда")) | C31: =IF($A31="","",SUMIFS(J_SUM,J_PER,$A31,J_CAT,"Налог")) | D31: =IF($A31="","",SUMIFS(J_SUM,J_PER,$A31,J_CAT,"Коммунальные услуги")) | E31: =IF($A31="","",SUMIFS(J_SUM,J_PER,$A31,J_CAT,"Залог")) | F31: =IF($A31="","",SUMIFS(J_SUM,J_PER,$A31,J_CAT,"Прочее")) | G31: =IF($A31="","",SUM($B31:$F31))
A32: =IF(История!$A$31="","",История!$A$31) | B32: =IF($A32="","",SUMIFS(J_SUM,J_PER,$A32,J_CAT,"Аренда")) | C32: =IF($A32="","",SUMIFS(J_SUM,J_PER,$A32,J_CAT,"Налог")) | D32: =IF($A32="","",SUMIFS(J_SUM,J_PER,$A32,J_CAT,"Коммунальные услуги")) | E32: =IF($A32="","",SUMIFS(J_SUM,J_PER,$A32,J_CAT,"Залог")) | F32: =IF($A32="","",SUMIFS(J_SUM,J_PER,$A32,J_CAT,"Прочее")) | G32: =IF($A32="","",SUM($B32:$F32))
A33: =IF(История!$A$32="","",История!$A$32) | B33: =IF($A33="","",SUMIFS(J_SUM,J_PER,$A33,J_CAT,"Аренда")) | C33: =IF($A33="","",SUMIFS(J_SUM,J_PER,$A33,J_CAT,"Налог")) | D33: =IF($A33="","",SUMIFS(J_SUM,J_PER,$A33,J_CAT,"Коммунальные услуги")) | E33: =IF($A33="","",SUMIFS(J_SUM,J_PER,$A33,J_CAT,"Залог")) | F33: =IF($A33="","",SUMIFS(J_SUM,J_PER,$A33,J_CAT,"Прочее")) | G33: =IF($A33="","",SUM($B33:$F33))
A34: =IF(История!$A$33="","",История!$A$33) | B34: =IF($A34="","",SUMIFS(J_SUM,J_PER,$A34,J_CAT,"Аренда")) | C34: =IF($A34="","",SUMIFS(J_SUM,J_PER,$A34,J_CAT,"Налог")) | D34: =IF($A34="","",SUMIFS(J_SUM,J_PER,$A34,J_CAT,"Коммунальные услуги")) | E34: =IF($A34="","",SUMIFS(J_SUM,J_PER,$A34,J_CAT,"Залог")) | F34: =IF($A34="","",SUMIFS(J_SUM,J_PER,$A34,J_CAT,"Прочее")) | G34: =IF($A34="","",SUM($B34:$F34))
A35: =IF(История!$A$34="","",История!$A$34) | B35: =IF($A35="","",SUMIFS(J_SUM,J_PER,$A35,J_CAT,"Аренда")) | C35: =IF($A35="","",SUMIFS(J_SUM,J_PER,$A35,J_CAT,"Налог")) | D35: =IF($A35="","",SUMIFS(J_SUM,J_PER,$A35,J_CAT,"Коммунальные услуги")) | E35: =IF($A35="","",SUMIFS(J_SUM,J_PER,$A35,J_CAT,"Залог")) | F35: =IF($A35="","",SUMIFS(J_SUM,J_PER,$A35,J_CAT,"Прочее")) | G35: =IF($A35="","",SUM($B35:$F35))
A36: =IF(История!$A$35="","",История!$A$35) | B36: =IF($A36="","",SUMIFS(J_SUM,J_PER,$A36,J_CAT,"Аренда")) | C36: =IF($A36="","",SUMIFS(J_SUM,J_PER,$A36,J_CAT,"Налог")) | D36: =IF($A36="","",SUMIFS(J_SUM,J_PER,$A36,J_CAT,"Коммунальные услуги")) | E36: =IF($A36="","",SUMIFS(J_SUM,J_PER,$A36,J_CAT,"Залог")) | F36: =IF($A36="","",SUMIFS(J_SUM,J_PER,$A36,J_CAT,"Прочее")) | G36: =IF($A36="","",SUM($B36:$F36))
A37: =IF(История!$A$36="","",История!$A$36) | B37: =IF($A37="","",SUMIFS(J_SUM,J_PER,$A37,J_CAT,"Аренда")) | C37: =IF($A37="","",SUMIFS(J_SUM,J_PER,$A37,J_CAT,"Налог")) | D37: =IF($A37="","",SUMIFS(J_SUM,J_PER,$A37,J_CAT,"Коммунальные услуги")) | E37: =IF($A37="","",SUMIFS(J_SUM,J_PER,$A37,J_CAT,"Залог")) | F37: =IF($A37="","",SUMIFS(J_SUM,J_PER,$A37,J_CAT,"Прочее")) | G37: =IF($A37="","",SUM($B37:$F37))
A38: =IF(История!$A$37="","",История!$A$37) | B38: =IF($A38="","",SUMIFS(J_SUM,J_PER,$A38,J_CAT,"Аренда")) | C38: =IF($A38="","",SUMIFS(J_SUM,J_PER,$A38,J_CAT,"Налог")) | D38: =IF($A38="","",SUMIFS(J_SUM,J_PER,$A38,J_CAT,"Коммунальные услуги")) | E38: =IF($A38="","",SUMIFS(J_SUM,J_PER,$A38,J_CAT,"Залог")) | F38: =IF($A38="","",SUMIFS(J_SUM,J_PER,$A38,J_CAT,"Прочее")) | G38: =IF($A38="","",SUM($B38:$F38))
A39: =IF(История!$A$38="","",История!$A$38) | B39: =IF($A39="","",SUMIFS(J_SUM,J_PER,$A39,J_CAT,"Аренда")) | C39: =IF($A39="","",SUMIFS(J_SUM,J_PER,$A39,J_CAT,"Налог")) | D39: =IF($A39="","",SUMIFS(J_SUM,J_PER,$A39,J_CAT,"Коммунальные услуги")) | E39: =IF($A39="","",SUMIFS(J_SUM,J_PER,$A39,J_CAT,"Залог")) | F39: =IF($A39="","",SUMIFS(J_SUM,J_PER,$A39,J_CAT,"Прочее")) | G39: =IF($A39="","",SUM($B39:$F39))
A40: =IF(История!$A$39="","",История!$A$39) | B40: =IF($A40="","",SUMIFS(J_SUM,J_PER,$A40,J_CAT,"Аренда")) | C40: =IF($A40="","",SUMIFS(J_SUM,J_PER,$A40,J_CAT,"Налог")) | D40: =IF($A40="","",SUMIFS(J_SUM,J_PER,$A40,J_CAT,"Коммунальные услуги")) | E40: =IF($A40="","",SUMIFS(J_SUM,J_PER,$A40,J_CAT,"Залог")) | F40: =IF($A40="","",SUMIFS(J_SUM,J_PER,$A40,J_CAT,"Прочее")) | G40: =IF($A40="","",SUM($B40:$F40))
A41: =IF(История!$A$40="","",История!$A$40) | B41: =IF($A41="","",SUMIFS(J_SUM,J_PER,$A41,J_CAT,"Аренда")) | C41: =IF($A41="","",SUMIFS(J_SUM,J_PER,$A41,J_CAT,"Налог")) | D41: =IF($A41="","",SUMIFS(J_SUM,J_PER,$A41,J_CAT,"Коммунальные услуги")) | E41: =IF($A41="","",SUMIFS(J_SUM,J_PER,$A41,J_CAT,"Залог")) | F41: =IF($A41="","",SUMIFS(J_SUM,J_PER,$A41,J_CAT,"Прочее")) | G41: =IF($A41="","",SUM($B41:$F41))
A42: =IF(История!$A$41="","",История!$A$41) | B42: =IF($A42="","",SUMIFS(J_SUM,J_PER,$A42,J_CAT,"Аренда")) | C42: =IF($A42="","",SUMIFS(J_SUM,J_PER,$A42,J_CAT,"Налог")) | D42: =IF($A42="","",SUMIFS(J_SUM,J_PER,$A42,J_CAT,"Коммунальные услуги")) | E42: =IF($A42="","",SUMIFS(J_SUM,J_PER,$A42,J_CAT,"Залог")) | F42: =IF($A42="","",SUMIFS(J_SUM,J_PER,$A42,J_CAT,"Прочее")) | G42: =IF($A42="","",SUM($B42:$F42))
...

Sheet Справочники
A1: СПРАВОЧНИКИ И НАСТРОЙКИ
A2: Списки ниже подставляются в выпадающие меню журнала — их можно менять
A4: НАСТРОЙКИ РАСЧЁТА
A5: Ставка налога (НПД/НДФЛ) | B5: 0.06 | C5: Используется в карточке «Оплачено налогов» для справочного расчёта
A6: Плановая коммуналка, ₽/мес | B6: 5000 | C6: Ориентир для сравнения фактических платежей
A7: Напомнить за N дней до срока | B7: 3 | C7: Через сколько дней до срока подсвечивать платёж
A9: СПИСКИ ДЛЯ ВЫПАДАЮЩИХ МЕНЮ
A10: Категории платежей | C10: Способы оплаты | D10: Статусы (справочно) | E10: Годы
A11: Аренда | C11: Наличные | D11: ✔ Оплачено | E11: =IF(Главная!$B$7="","",YEAR(Главная!$B$7)+0)
A12: Налог | C12: Перевод СБП | D12: ◐ Частично | E12: =IF(Главная!$B$7="","",YEAR(Главная!$B$7)+1)
A13: Коммунальные услуги | C13: Банковская карта | D13: ⚠ Просрочено | E13: =IF(Главная!$B$7="","",YEAR(Главная!$B$7)+2)
A14: Залог | C14: Расчётный счёт | D14: ⏳ Ожидается | E14: =IF(Главная!$B$7="","",YEAR(Главная!$B$7)+3)
A15: Прочее | C15: Почтовый перевод | D15: — | E15: =IF(Главная!$B$7="","",YEAR(Главная!$B$7)+4)
C16: Другое
A18: ЛЕГЕНДА ОФОРМЛЕНИЯ
A19: Белое поле с бирюзовой рамкой | B19: ячейка для ручного ввода — её можно заполнять
A20: Сиреневая ячейка со значком 🤖 | B20: формула, защищена от изменений
A21: Зелёная подсветка | B21: оплачено полностью / ошибок нет
A22: Янтарная подсветка | B22: частичная оплата или незаполненное поле
A23: Красная подсветка | B23: просрочка, долг или ошибка ввода
A25: ПАМЯТКА: ПРИМЕР ЗАПОЛНЕНИЯ СТРОКИ ЖУРНАЛА
A26: Дата | B26: 05.08.2026 | D26: Это только образец на память — копировать ничего не нужно. Столбец «Месяц» можно не заполнять: платёж зачтётся за месяц своей даты, а колонка «🤖 Учтён за месяц» покажет результат. Значения выбираются из списка или вписываются вручную. Списки категорий и способов оплаты зашиты в проверку данных на листе «Регистрация»: чтобы изменить, выделите столбец и откройте «Данные → Проверка данных».
A27: Категория | B27: Аренда
A28: Месяц (период) | B28: август 2026
A29: Сумма | B29: 45 000 ₽
A30: Способ | B30: Перевод СБП
