Workbook

Sheet Параметры
A1: ПАРАМЕТРЫ ПАКЕТА ДОКУМЕНТОВ (единый источник данных)
A2: Жёлтые ячейки с синим шрифтом — исходные данные: заполняйте/меняйте только их. Все остальные листы обновятся автоматически.
A4: 1. ДОГОВОР
A5: Номер договора | B5: ПД-14/2026
A6: Дата договора | B6: 46220
A7: Место заключения | B7: г. Москва
A8: Дата начала работ | B8: 46235
A9: Дата окончания работ | B9: 46356
A10: Аванс, % от цены договора | B10: 0.3
A11: Гарантийный срок, мес. | B11: 24
A12: Ставка НДС | B12: 0.2
A13: Неустойка за просрочку, % за каждый день | B13: 0.001
A15: 2. ЗАКАЗЧИК
A16: Полное наименование | B16: Общество с ограниченной ответственностью «Специализированный застройщик «Новый квартал»
A17: Краткое наименование | B17: ООО «СЗ «Новый квартал»
A18: ИНН | B18: 7701234567
A19: КПП | B19: 770101001
A20: ОГРН | B20: 1157746123456
A21: Юридический адрес | B21: 101000, г. Москва, ул. Мясницкая, д. 10, офис 5
A22: Банк | B22: ПАО «Сбербанк России», г. Москва
A23: БИК | B23: 044525225
A24: Расчётный счёт | B24: 40702810438000012345
A25: Корреспондентский счёт | B25: 30101810400000000225
A26: Должность руководителя | B26: Генеральный директор
A27: ФИО руководителя (полностью) | B27: Иванов Иван Иванович
... A36: E-mail | B36: info@nk-dev.ru
A38: 3. ПОДРЯДЧИК
A39: Полное наименование | B39: Общество с ограниченной ответственностью «ЛифтМонтажСервис»
A40: Краткое наименование | B40: ООО «ЛифтМонтажСервис»
A41: ИНН | B41: 7725678901
A42: КПП | B42: 772501001
A43: ОГРН | B43: 1187746654321
A44: Юридический адрес | B44: 115280, г. Москва, ул. Ленинская Слобода, д. 19, стр. 2
A45: Банк | B45: АО «Альфа-Банк», г. Москва
A46: БИК | B46: 044525593
A47: Расчётный счёт | B47: 40702810102300067890
A48: Корреспондентский счёт | B48: 30101810200000000593
A49: Должность руководителя | B49: Генеральный директор
A50: ФИО руководителя (полностью) | B50: Петров Пётр Петрович
... A57: E-mail | B57: office@liftmontag.ru
...

Sheet Смета
A1: ="ЛОКАЛЬНАЯ СМЕТА № 1 к договору подряда № "&Параметры!$B$5&" от "&TEXT(Параметры!$B$6,"DD.MM.YYYY") -> ЛОКАЛЬНАЯ СМЕТА № 1 к договору подряда № ПД-14/2026 от 17.07.2026
A2: ="Объект: "&Параметры!$B$60&", "&Параметры!$B$61 -> Объект: Многоквартирный жилой дом, корпус 3, г. Москва, ул. Полярная, д. 25, корп. 3
A4: № | B4: Наименование работ | C4: Ед. изм. | D4: Кол-во | E4: Цена за ед., руб. без НДС | F4: Стоимость, руб. без НДС
A5: 1 | B5: Демонтаж существующего лифтового оборудования | C5: шт. | D5: 2 | E5: 180000 | F5: =D5*E5 -> 360000
A6: 2 | B6: Монтаж направляющих кабины и противовеса | C6: компл. | D6: 2 | E6: 220000 | F6: =D6*E6 -> 440000
A7: 3 | B7: Монтаж лебёдки и рамы главного привода | C7: шт. | D7: 2 | E7: 150000 | F7: =D7*E7 -> 300000
A8: 4 | B8: Монтаж кабины лифта | C8: шт. | D8: 2 | E8: 260000 | F8: =D8*E8 -> 520000
A9: 5 | B9: Монтаж противовеса | C9: шт. | D9: 2 | E9: 90000 | F9: =D9*E9 -> 180000
A10: 6 | B10: Монтаж дверей шахты | C10: шт. | D10: 18 | E10: 25000 | F10: =D10*E10 -> 450000
A11: 7 | B11: Электромонтажные работы (станция управления, освещение и разводка по шахте) | C11: компл. | D11: 2 | E11: 190000 | F11: =D11*E11 -> 380000
A12: 8 | B12: Монтаж обрамлений дверных проёмов | C12: шт. | D12: 18 | E12: 12000 | F12: =D12*E12 -> 216000
A13: 9 | B13: Пусконаладочные работы | C13: компл. | D13: 2 | E13: 160000 | F13: =D13*E13 -> 320000
A14: 10 | B14: Полное техническое освидетельствование и сдача лифтов в эксплуатацию | C14: компл. | D14: 2 | E14: 85000 | F14: =D14*E14 -> 170000
A15: Итого без НДС | F15: =SUM(F5:F14) -> 3336000
A16: ="НДС ("&TEXT(Параметры!$B$12,"0%")&")" -> НДС (20%) | F16: =F15*Параметры!$B$12 -> 667200
A17: Всего с НДС | F17: =F15+F16 -> 4003200
A19: Жёлтые ячейки — редактируемые данные сметы. При добавлении строк вставляйте их ВНУТРЬ таблицы (между первой и последней позицией) и добавляйте зеркальную строку в акт КС-2.

Sheet Спецификация
A1: ="СПЕЦИФИКАЦИЯ № 1 (оборудование и материалы) к договору подряда № "&Параметры!$B$5&" от "&TEXT(Параметры!$B$6,"DD.MM.YYYY") -> СПЕЦИФИКАЦИЯ № 1 (оборудование и материалы) к договору подряда № ПД-14/2026 от 17.07.2026
A2: ="Объект: "&Параметры!$B$60&", "&Параметры!$B$61 -> Объект: Многоквартирный жилой дом, корпус 3, г. Москва, ул. Полярная, д. 25, корп. 3
A4: № | B4: Наименование оборудования / материалов | C4: Ед. изм. | D4: Кол-во | E4: Цена за ед., руб. без НДС | F4: Стоимость, руб. без НДС
A5: 1 | B5: Лифт пассажирский, г/п 630 кг, скорость 1,0 м/с, 9 остановок (комплект поставки завода-изготовителя) | C5: шт. | D5: 2 | E5: 2950000 | F5: =D5*E5 -> 5900000
A6: 2 | B6: Обрамление дверного портала из нержавеющей стали | C6: компл. | D6: 18 | E6: 15000 | F6: =D6*E6 -> 270000
A7: 3 | B7: Кабельная продукция (силовые и слаботочные линии, комплект на шахту) | C7: компл. | D7: 2 | E7: 45000 | F7: =D7*E7 -> 90000
A8: 4 | B8: Металлоконструкции для крепления направляющих | C8: компл. | D8: 2 | E8: 60000 | F8: =D8*E8 -> 120000
A9: 5 | B9: Крепёжные изделия и расходные материалы | C9: компл. | D9: 2 | E9: 25000 | F9: =D9*E9 -> 50000
A10: 6 | B10: Светильники освещения шахты | C10: шт. | D10: 20 | E10: 1800 | F10: =D10*E10 -> 36000
A11: Итого без НДС | F11: =SUM(F5:F10) -> 6466000
A12: ="НДС ("&TEXT(Параметры!$B$12,"0%")&")" -> НДС (20%) | F12: =F11*Параметры!$B$12 -> 1293200
A13: Всего с НДС | F13: =F11+F12 -> 7759200

Sheet КП
A1: =Параметры!$B$40 -> ООО «ЛифтМонтажСервис»
A2: =Параметры!$B$44&", тел. "&Параметры!$B$56&", "&Параметры!$B$57 -> 115280, г. Москва, ул. Ленинская Слобода, д. 19, стр. 2, тел. +7 (495) 987-65-43, office@liftmontag.ru
A3: ="ИНН "&Параметры!$B$41&" / КПП "&Параметры!$B$42&", ОГРН "&Параметры!$B$43 -> ИНН 7725678901 / КПП 772501001, ОГРН 1187746654321
A5: ="КОММЕРЧЕСКОЕ ПРЕДЛОЖЕНИЕ № "&Параметры!$B$66&" от "&TEXT(Параметры!$B$67,"DD.MM.YYYY") -> КОММЕРЧЕСКОЕ ПРЕДЛОЖЕНИЕ № 14-КП от 17.07.2026
A7: ="Кому: "&Параметры!$B$17&", "&Параметры!$B$26&" "&Параметры!$B$28 -> Кому: ООО «СЗ «Новый квартал», Генеральный директор Иванов И.И.
A9: =Параметры!$B$40&" предлагает выполнить комплекс работ по монтажу и пусконаладке лифтового оборудования ("&Параметры!$B$63&", "&Параметры!$B$62&" шт.) на объекте: "&Параметры!$B$60&" по адресу: "&Параметры!$B$61&"." -> ООО «ЛифтМонтажСервис» предлагает выполнить комплекс работ по монтажу и пусконаладке лифтового оборудования (лифт пассажирский, г/п 630 кг, скорость 1,0 м/с, 9 остановок, 2 шт.) на объекте: Многоквартирный жилой дом, корпус 3 по адресу: г. Москва, ул. Полярная, д. 25, корп. 3.
A11: № | B11: Наименование | C11: Стоимость без НДС, руб. | D11: ="НДС ("&TEXT(Параметры!$B$12,"0%")&"), руб." -> НДС (20%), руб. | E11: Стоимость с НДС, руб.
A12: 1 | B12: Строительно-монтажные и пусконаладочные работы (лист «Смета») | C12: =Смета!$F$15 -> 3336000 | D12: =Смета!$F$16 -> 667200 | E12: =Смета!$F$17 -> 4003200
A13: 2 | B13: Лифтовое оборудование и материалы (лист «Спецификация») | C13: =Спецификация!$F$11 -> 6466000 | D13: =Спецификация!$F$12 -> 1293200 | E13: =Спецификация!$F$13 -> 7759200
A14: ИТОГО | C14: =SUM(C12:C13) -> 9802000 | D14: =SUM(D12:D13) -> 1960400 | E14: =SUM(E12:E13) -> 11762400
A16: ="Срок выполнения работ: с "&TEXT(Параметры!$B$8,"DD.MM.YYYY")&" по "&TEXT(Параметры!$B$9,"DD.MM.YYYY")&"." -> Срок выполнения работ: с 01.08.2026 по 30.11.2026.
A17: ="Условия оплаты: аванс "&TEXT(Параметры!$B$10,"0%")&", окончательный расчёт — в течение 10 банковских дней после подписания актов по формам КС-2 и КС-3." -> Условия оплаты: аванс 30%, окончательный расчёт — в течение 10 банковских дней после подписания актов по формам КС-2 и КС-3.
A18: ="Гарантия на выполненные работы: "&Параметры!$B$11&" мес. Срок действия предложения: 30 календарных дней." -> Гарантия на выполненные работы: 24 мес. Срок действия предложения: 30 календарных дней.
A21: =Параметры!$B$49&" "&Параметры!$B$40 -> Генеральный директор ООО «ЛифтМонтажСервис» | E21: ="_____________ /"&Параметры!$B$51&"/" -> _____________ /Петров П.П./

Sheet КС-2
G1: Унифицированная форма № КС-2
A2: ="Заказчик (Генподрядчик): "&Параметры!$B$16&", "&Параметры!$B$21&", тел. "&Параметры!$B$35 -> Заказчик (Генподрядчик): Общество с ограниченной ответственностью «Специализированный застройщик «Новый квартал», 101000, г. Москва, ул. Мясницкая, д. 10, офис 5, тел. +7 (495) 123-45-67
A3: ="Подрядчик (Субподрядчик): "&Параметры!$B$39&", "&Параметры!$B$44&", тел. "&Параметры!$B$56 -> Подрядчик (Субподрядчик): Общество с ограниченной ответственностью «ЛифтМонтажСервис», 115280, г. Москва, ул. Ленинская Слобода, д. 19, стр. 2, тел. +7 (495) 987-65-43
A4: ="Стройка (объект): "&Параметры!$B$60&", "&Параметры!$B$61 -> Стройка (объект): Многоквартирный жилой дом, корпус 3, г. Москва, ул. Полярная, д. 25, корп. 3
A5: ="Договор подряда: № "&Параметры!$B$5&" от "&TEXT(Параметры!$B$6,"DD.MM.YYYY") -> Договор подряда: № ПД-14/2026 от 17.07.2026
A7: ="АКТ О ПРИЕМКЕ ВЫПОЛНЕННЫХ РАБОТ № "&Параметры!$B$68&" от "&TEXT(Параметры!$B$69,"DD.MM.YYYY") -> АКТ О ПРИЕМКЕ ВЫПОЛНЕННЫХ РАБОТ № 1 от 30.11.2026
A8: ="Отчётный период: с "&TEXT(Параметры!$B$70,"DD.MM.YYYY")&" по "&TEXT(Параметры!$B$71,"DD.MM.YYYY") -> Отчётный период: с 01.08.2026 по 30.11.2026
A10: № п/п | B10: № поз. по смете | C10: Наименование работ | D10: Ед. изм. | E10: Кол-во | F10: Цена за ед., руб. | G10: Стоимость, руб. без НДС
A11: 1 | B11: =Смета!A5 -> 1 | C11: =Смета!B5 -> Демонтаж существующего лифтового оборудования | D11: =Смета!C5 -> шт. | E11: =Смета!D5 -> 2 | F11: =Смета!E5 -> 180000 | G11: =E11*F11 -> 360000
A12: 2 | B12: =Смета!A6 -> 2 | C12: =Смета!B6 -> Монтаж направляющих кабины и противовеса | D12: =Смета!C6 -> компл. | E12: =Смета!D6 -> 2 | F12: =Смета!E6 -> 220000 | G12: =E12*F12 -> 440000
A13: 3 | B13: =Смета!A7 -> 3 | C13: =Смета!B7 -> Монтаж лебёдки и рамы главного привода | D13: =Смета!C7 -> шт. | E13: =Смета!D7 -> 2 | F13: =Смета!E7 -> 150000 | G13: =E13*F13 -> 300000
A14: 4 | B14: =Смета!A8 -> 4 | C14: =Смета!B8 -> Монтаж кабины лифта | D14: =Смета!C8 -> шт. | E14: =Смета!D8 -> 2 | F14: =Смета!E8 -> 260000 | G14: =E14*F14 -> 520000
A15: 5 | B15: =Смета!A9 -> 5 | C15: =Смета!B9 -> Монтаж противовеса | D15: =Смета!C9 -> шт. | E15: =Смета!D9 -> 2 | F15: =Смета!E9 -> 90000 | G15: =E15*F15 -> 180000
A16: 6 | B16: =Смета!A10 -> 6 | C16: =Смета!B10 -> Монтаж дверей шахты | D16: =Смета!C10 -> шт. | E16: =Смета!D10 -> 18 | F16: =Смета!E10 -> 25000 | G16: =E16*F16 -> 450000
A17: 7 | B17: =Смета!A11 -> 7 | C17: =Смета!B11 -> Электромонтажные работы (станция управления, освещение и разводка по шахте) | D17: =Смета!C11 -> компл. | E17: =Смета!D11 -> 2 | F17: =Смета!E11 -> 190000 | G17: =E17*F17 -> 380000
A18: 8 | B18: =Смета!A12 -> 8 | C18: =Смета!B12 -> Монтаж обрамлений дверных проёмов | D18: =Смета!C12 -> шт. | E18: =Смета!D12 -> 18 | F18: =Смета!E12 -> 12000 | G18: =E18*F18 -> 216000
A19: 9 | B19: =Смета!A13 -> 9 | C19: =Смета!B13 -> Пусконаладочные работы | D19: =Смета!C13 -> компл. | E19: =Смета!D13 -> 2 | F19: =Смета!E13 -> 160000 | G19: =E19*F19 -> 320000
A20: 10 | B20: =Смета!A14 -> 10 | C20: =Смета!B14 -> Полное техническое освидетельствование и сдача лифтов в эксплуатацию | D20: =Смета!C14 -> компл. | E20: =Смета!D14 -> 2 | F20: =Смета!E14 -> 85000 | G20: =E20*F20 -> 170000
A21: Итого без НДС | G21: =SUM(G11:G20) -> 3336000
A22: ="НДС ("&TEXT(Параметры!$B$12,"0%")&"), справочно" -> НДС (20%), справочно | G22: =G21*Параметры!$B$12 -> 667200
A23: Всего с НДС, справочно | G23: =G21+G22 -> 4003200
A25: ="Сдал: "&Параметры!$B$49&" "&Параметры!$B$40 -> Сдал: Генеральный директор ООО «ЛифтМонтажСервис» | F25: ="__________ /"&Параметры!$B$51&"/" -> __________ /Петров П.П./
A27: ="Принял: "&Параметры!$B$26&" "&Параметры!$B$17 -> Принял: Генеральный директор ООО «СЗ «Новый квартал» | F27: ="__________ /"&Параметры!$B$28&"/" -> __________ /Иванов И.И./

Sheet КС-3
E1: Унифицированная форма № КС-3
A2: ="Заказчик (Генподрядчик): "&Параметры!$B$16&", "&Параметры!$B$21 -> Заказчик (Генподрядчик): Общество с ограниченной ответственностью «Специализированный застройщик «Новый квартал», 101000, г. Москва, ул. Мясницкая, д. 10, офис 5
A3: ="Подрядчик (Субподрядчик): "&Параметры!$B$39&", "&Параметры!$B$44 -> Подрядчик (Субподрядчик): Общество с ограниченной ответственностью «ЛифтМонтажСервис», 115280, г. Москва, ул. Ленинская Слобода, д. 19, стр. 2
A4: ="Стройка (объект): "&Параметры!$B$60&", "&Параметры!$B$61 -> Стройка (объект): Многоквартирный жилой дом, корпус 3, г. Москва, ул. Полярная, д. 25, корп. 3
A5: ="Договор подряда: № "&Параметры!$B$5&" от "&TEXT(Параметры!$B$6,"DD.MM.YYYY") -> Договор подряда: № ПД-14/2026 от 17.07.2026
A7: ="СПРАВКА О СТОИМОСТИ ВЫПОЛНЕННЫХ РАБОТ И ЗАТРАТ № "&Параметры!$B$72&" от "&TEXT(Параметры!$B$73,"DD.MM.YYYY") -> СПРАВКА О СТОИМОСТИ ВЫПОЛНЕННЫХ РАБОТ И ЗАТРАТ № 1 от 30.11.2026
A8: ="Отчётный период: с "&TEXT(Параметры!$B$70,"DD.MM.YYYY")&" по "&TEXT(Параметры!$B$71,"DD.MM.YYYY") -> Отчётный период: с 01.08.2026 по 30.11.2026
A10: № | B10: Наименование работ и затрат | C10: С начала проведения работ, руб. | D10: С начала года, руб. | E10: В том числе за отчётный период, руб.
A11: 1 | B11: ="Строительно-монтажные и пусконаладочные работы (акт КС-2 № "&Параметры!$B$68&" от "&TEXT(Параметры!$B$69,"DD.MM.YYYY")&")" -> Строительно-монтажные и пусконаладочные работы (акт КС-2 № 1 от 30.11.2026) | C11: ='КС-2'!$G$21 -> 3336000 | D11: =C11 -> 3336000 | E11: =C11 -> 3336000
A12: 2 | B12: ="Лифтовое оборудование и материалы (Спецификация № 1)" -> Лифтовое оборудование и материалы (Спецификация № 1) | C12: =Спецификация!$F$11 -> 6466000 | D12: =C12 -> 6466000 | E12: =C12 -> 6466000
B13: Итого | C13: =SUM(C11:C12) -> 9802000 | D13: =SUM(D11:D12) -> 9802000 | E13: =SUM(E11:E12) -> 9802000
B14: ="Сумма НДС ("&TEXT(Параметры!$B$12,"0%")&")" -> Сумма НДС (20%) | C14: =C13*Параметры!$B$12 -> 1960400 | D14: =D13*Параметры!$B$12 -> 1960400 | E14: =E13*Параметры!$B$12 -> 1960400
B15: Всего с учётом НДС | C15: =C13+C14 -> 11762400 | D15: =D13+D14 -> 11762400 | E15: =E13+E14 -> 11762400
A17: ="Заказчик: "&Параметры!$B$26&" "&Параметры!$B$17 -> Заказчик: Генеральный директор ООО «СЗ «Новый квартал» | E17: ="__________ /"&Параметры!$B$28&"/" -> __________ /Иванов И.И./
A19: ="Подрядчик: "&Параметры!$B$49&" "&Параметры!$B$40 -> Подрядчик: Генеральный директор ООО «ЛифтМонтажСервис» | E19: ="__________ /"&Параметры!$B$51&"/" -> __________ /Петров П.П./

Sheet Счёт
A1: ="Банк получателя: "&Параметры!$B$45 -> Банк получателя: АО «Альфа-Банк», г. Москва | E1: БИК | F1: =Параметры!$B$46 -> 044525593
E2: К/с | F2: =Параметры!$B$48 -> 30101810200000000593
A3: ="Получатель: "&Параметры!$B$40&", ИНН "&Параметры!$B$41&" / КПП "&Параметры!$B$42 -> Получатель: ООО «ЛифтМонтажСервис», ИНН 7725678901 / КПП 772501001 | E3: Р/с | F3: =Параметры!$B$47 -> 40702810102300067890
A5: ="СЧЁТ НА ОПЛАТУ № "&Параметры!$B$74&" от "&TEXT(Параметры!$B$75,"DD.MM.YYYY") -> СЧЁТ НА ОПЛАТУ № 118 от 30.11.2026
A7: ="Поставщик (Исполнитель): "&Параметры!$B$39&", "&Параметры!$B$44 -> Поставщик (Исполнитель): Общество с ограниченной ответственностью «ЛифтМонтажСервис», 115280, г. Москва, ул. Ленинская Слобода, д. 19, стр. 2
A8: ="Покупатель (Заказчик): "&Параметры!$B$16&", ИНН "&Параметры!$B$18&" / КПП "&Параметры!$B$19&", "&Параметры!$B$21 -> Покупатель (Заказчик): Общество с ограниченной ответственностью «Специализированный застройщик «Новый квартал», ИНН 7701234567 / КПП 770101001, 101000, г. Москва, ул. Мясницкая, д. 10, офис 5
A9: ="Основание: договор подряда № "&Параметры!$B$5&" от "&TEXT(Параметры!$B$6,"DD.MM.YYYY") -> Основание: договор подряда № ПД-14/2026 от 17.07.2026
A11: № | B11: Наименование работ (услуг), товаров | C11: Кол-во | D11: Ед. изм. | E11: Цена, руб. без НДС | F11: Сумма, руб. без НДС
A12: 1 | B12: ="Работы по монтажу и пусконаладке лифтового оборудования по договору № "&Параметры!$B$5&" от "&TEXT(Параметры!$B$6,"DD.MM.YYYY")&" (акт КС-2 № "&Параметры!$B$68&", справка КС-3 № "&Параметры!$B$72&")" -> Работы по монтажу и пусконаладке лифтового оборудования по договору № ПД-14/2026 от 17.07.2026 (акт КС-2 № 1, справка КС-3 № 1) | C12: 1 | D12: компл. | E12: ='КС-2'!$G$21 -> 3336000 | F12: =C12*E12 -> 3336000
A13: 2 | B13: ="Лифтовое оборудование и материалы (Спецификация № 1 к договору)" -> Лифтовое оборудование и материалы (Спецификация № 1 к договору) | C13: 1 | D13: компл. | E13: =Спецификация!$F$11 -> 6466000 | F13: =C13*E13 -> 6466000
A14: Итого без НДС | F14: =SUM(F12:F13) -> 9802000
A15: ="НДС ("&TEXT(Параметры!$B$12,"0%")&")" -> НДС (20%) | F15: =F14*Параметры!$B$12 -> 1960400
A16: Всего к оплате с НДС | F16: =F14+F15 -> 11762400
A18: ="Всего наименований "&COUNT(Счёт!A12:A13)&", на сумму "&TEXT(F16,"#,##0.00")&" руб." -> Всего наименований 2, на сумму 11,762,400.00 руб.
A19: ="Сумма прописью: "&Параметры!$B$81 -> Сумма прописью: Одиннадцать миллионов семьсот шестьдесят две тысячи четыреста рублей 00 копеек
A22: ="Руководитель: "&Параметры!$B$49 -> Руководитель: Генеральный директор | E22: ="__________ /"&Параметры!$B$51&"/" -> __________ /Петров П.П./
A24: ="Главный бухгалтер:" -> Главный бухгалтер: | E24: ="__________ /"&Параметры!$B$55&"/" -> __________ /Сидорова А.В./

Sheet Сопроводительное письмо
A1: =Параметры!$B$39 -> Общество с ограниченной ответственностью «ЛифтМонтажСервис»
A2: =Параметры!$B$44&", тел. "&Параметры!$B$56&", "&Параметры!$B$57 -> 115280, г. Москва, ул. Ленинская Слобода, д. 19, стр. 2, тел. +7 (495) 987-65-43, office@liftmontag.ru
A3: ="ИНН "&Параметры!$B$41&" / КПП "&Параметры!$B$42&", ОГРН "&Параметры!$B$43 -> ИНН 7725678901 / КПП 772501001, ОГРН 1187746654321
A5: ="Исх. № "&Параметры!$B$76&" от "&TEXT(Параметры!$B$77,"DD.MM.YYYY") -> Исх. № 245 от 01.12.2026
D6: =Параметры!$B$32 -> Генеральному директору
D7: =Параметры!$B$17 -> ООО «СЗ «Новый квартал»
D8: =Параметры!$B$33 -> Иванову И.И.
A10: ="О направлении документов по договору № "&Параметры!$B$5&" от "&TEXT(Параметры!$B$6,"DD.MM.YYYY") -> О направлении документов по договору № ПД-14/2026 от 17.07.2026
A12: ="Уважаемый "&Параметры!$B$34&"!" -> Уважаемый Иван Иванович!
A13: ="В связи с завершением работ по монтажу и пусконаладке лифтового оборудования на объекте: "&Параметры!$B$60&" по адресу: "&Параметры!$B$61&" направляем Вам для рассмотрения и подписания комплект отчётных документов по договору подряда № "&Параметры!$B$5&" от "&TEXT(Параметры!$B$6,"DD.MM.YYYY")&"." -> В связи с завершением работ по монтажу и пусконаладке лифтового оборудования на объекте: Многоквартирный жилой дом, корпус 3 по адресу: г. Москва, ул. Полярная, д. 25, корп. 3 направляем Вам для рассмотрения и подписания комплект отчётных документов по договору подряда № ПД-14/2026 от 17.07.2026.
A14: ="Просим в течение 5 (пяти) рабочих дней с даты получения подписать документы и вернуть по одному экземпляру в наш адрес либо направить мотивированный отказ от подписания." -> Просим в течение 5 (пяти) рабочих дней с даты получения подписать документы и вернуть по одному экземпляру в наш адрес либо направить мотивированный отказ от подписания.
A16: Приложения:
A17: ="1. Акт о приёмке выполненных работ (КС-2) № "&Параметры!$B$68&" от "&TEXT(Параметры!$B$69,"DD.MM.YYYY")&" — в 2 экз." -> 1. Акт о приёмке выполненных работ (КС-2) № 1 от 30.11.2026 — в 2 экз.
A18: ="2. Справка о стоимости выполненных работ и затрат (КС-3) № "&Параметры!$B$72&" от "&TEXT(Параметры!$B$73,"DD.MM.YYYY")&" — в 2 экз." -> 2. Справка о стоимости выполненных работ и затрат (КС-3) № 1 от 30.11.2026 — в 2 экз.
A19: ="3. Счёт на оплату № "&Параметры!$B$74&" от "&TEXT(Параметры!$B$75,"DD.MM.YYYY")&" на сумму "&TEXT('КС-3'!$E$15,"#,##0.00")&" руб. с НДС — в 1 экз." -> 3. Счёт на оплату № 118 от 30.11.2026 на сумму 11,762,400.00 руб. с НДС — в 1 экз.
A22: =Параметры!$B$49&" "&Параметры!$B$40 -> Генеральный директор ООО «ЛифтМонтажСервис» | D22: ="_____________ /"&Параметры!$B$51&"/" -> _____________ /Петров П.П./

Sheet Договор
A1: ="ДОГОВОР ПОДРЯДА № "&Параметры!$B$5 -> ДОГОВОР ПОДРЯДА № ПД-14/2026
A2: =Параметры!$B$7 -> г. Москва | E2: =TEXT(Параметры!$B$6,"DD.MM.YYYY") -> 17.07.2026
A4: =Параметры!$B$16&" (далее — «Заказчик»), в лице "&Параметры!$B$30&" "&Параметры!$B$31&", действующего на основании "&Параметры!$B$29&", с одной стороны, и "&Параметры!$B$39&" (далее — «Подрядчик»), в лице "&Параметры!$B$53&" "&Параметры!$B$54&", действующего на основании "&Параметры!$B$52&", с другой стороны, совместно именуемые «Стороны», заключили настоящий Договор о нижеследующем:" -> Общество с ограниченной ответственностью «Специализированный застройщик «Новый квартал» (далее — «Заказчик»), в лице Генерального директора Иванова Ивана Ивановича, действующего на основании Устава, с одной стороны, и Общество с ограниченной ответственностью «ЛифтМонтажСервис» (далее — «Подрядчик»), в лице Генерального директора Петрова Петра Петровича, действующего на основании Устава, с другой стороны, совместно именуемые «Стороны», заключили настоящий Договор о нижеследующем:
A6: 1. ПРЕДМЕТ ДОГОВОРА
A7: ="1.1. Подрядчик обязуется выполнить комплекс работ по монтажу и пусконаладке лифтового оборудования ("&Параметры!$B$63&", "&Параметры!$B$62&" шт.) на объекте: "&Параметры!$B$60&" по адресу: "&Параметры!$B$61&" (далее — «Объект»), а Заказчик обязуется создать Подрядчику необходимые условия для выполнения работ, принять их результат и уплатить обусловленную Договором цену." -> 1.1. Подрядчик обязуется выполнить комплекс работ по монтажу и пусконаладке лифтового оборудования (лифт пассажирский, г/п 630 кг, скорость 1,0 м/с, 9 остановок, 2 шт.) на объекте: Многоквартирный жилой дом, корпус 3 по адресу: г. Москва, ул. Полярная, д. 25, корп. 3 (далее — «Объект»), а Заказчик обязуется создать Подрядчику необходимые условия для выполнения работ, принять их результат и уплатить обусловленную Договором цену.
A8: ="1.2. Состав, объёмы и стоимость работ определяются Локальной сметой № 1 (Приложение № 1) и Спецификацией № 1 (Приложение № 2), являющимися неотъемлемой частью настоящего Договора." -> 1.2. Состав, объёмы и стоимость работ определяются Локальной сметой № 1 (Приложение № 1) и Спецификацией № 1 (Приложение № 2), являющимися неотъемлемой частью настоящего Договора.
A10: 2. ЦЕНА ДОГОВОРА И ПОРЯДОК РАСЧЁТОВ
A11: ="2.1. Цена Договора составляет "&TEXT(КП!$E$14,"#,##0.00")&" ("&Параметры!$B$81&") руб., в том числе НДС ("&TEXT(Параметры!$B$12,"0%")&") — "&TEXT(КП!$D$14,"#,##0.00")&" руб." -> 2.1. Цена Договора составляет 11,762,400.00 (Одиннадцать миллионов семьсот шестьдесят две тысячи четыреста рублей 00 копеек) руб., в том числе НДС (20%) — 1,960,400.00 руб.
A12: ="2.2. Заказчик перечисляет Подрядчику аванс в размере "&TEXT(Параметры!$B$10,"0%")&" от цены Договора, что составляет "&TEXT(КП!$E$14*Параметры!$B$10,"#,##0.00")&" руб., в течение 5 (пяти) банковских дней с даты подписания настоящего Договора." -> 2.2. Заказчик перечисляет Подрядчику аванс в размере 30% от цены Договора, что составляет 3,528,720.00 руб., в течение 5 (пяти) банковских дней с даты подписания настоящего Договора.
A13: ="2.3. Окончательный расчёт производится Заказчиком в течение 10 (десяти) банковских дней после подписания Сторонами акта о приёмке выполненных работ (форма КС-2) и справки о стоимости выполненных работ и затрат (форма КС-3) на основании выставленного Подрядчиком счёта." -> 2.3. Окончательный расчёт производится Заказчиком в течение 10 (десяти) банковских дней после подписания Сторонами акта о приёмке выполненных работ (форма КС-2) и справки о стоимости выполненных работ и затрат (форма КС-3) на основании выставленного Подрядчиком счёта.
A15: 3. СРОКИ ВЫПОЛНЕНИЯ РАБОТ
A16: ="3.1. Начало работ: "&TEXT(Параметры!$B$8,"DD.MM.YYYY")&". Окончание работ: "&TEXT(Параметры!$B$9,"DD.MM.YYYY")&"." -> 3.1. Начало работ: 01.08.2026. Окончание работ: 30.11.2026.
A17: ="3.2. Сроки выполнения работ могут быть изменены по соглашению Сторон путём подписания дополнительного соглашения к настоящему Договору." -> 3.2. Сроки выполнения работ могут быть изменены по соглашению Сторон путём подписания дополнительного соглашения к настоящему Договору.
A19: 4. ОБЯЗАННОСТИ СТОРОН
A20: ="4.1. Подрядчик обязуется выполнить работы в соответствии с требованиями ТР ТС 011/2011 «Безопасность лифтов», проектной документацией и условиями настоящего Договора, своими силами, инструментами и механизмами." -> 4.1. Подрядчик обязуется выполнить работы в соответствии с требованиями ТР ТС 011/2011 «Безопасность лифтов», проектной документацией и условиями настоящего Договора, своими силами, инструментами и механизмами.
A21: ="4.2. Подрядчик обязуется обеспечить на Объекте соблюдение требований охраны труда, пожарной безопасности, а также вывоз строительного мусора, образовавшегося в результате выполнения работ." -> 4.2. Подрядчик обязуется обеспечить на Объекте соблюдение требований охраны труда, пожарной безопасности, а также вывоз строительного мусора, образовавшегося в результате выполнения работ.
A22: ="4.3. Заказчик обязуется передать Подрядчику по акту строительную готовность машинных помещений и шахт, обеспечить электроснабжение на период монтажа и допуск персонала Подрядчика на Объект." -> 4.3. Заказчик обязуется передать Подрядчику по акту строительную готовность машинных помещений и шахт, обеспечить электроснабжение на период монтажа и допуск персонала Подрядчика на Объект.
A23: ="4.4. Заказчик обязуется своевременно принять и оплатить выполненные работы в порядке, установленном разделом 2 настоящего Договора." -> 4.4. Заказчик обязуется своевременно принять и оплатить выполненные работы в порядке, установленном разделом 2 настоящего Договора.
A25: 5. ПОРЯДОК СДАЧИ И ПРИЁМКИ РАБОТ
A26: ="5.1. По завершении работ Подрядчик передаёт Заказчику акт по форме КС-2, справку по форме КС-3 и исполнительную документацию сопроводительным письмом." -> 5.1. По завершении работ Подрядчик передаёт Заказчику акт по форме КС-2, справку по форме КС-3 и исполнительную документацию сопроводительным письмом.
A27: ="5.2. Заказчик в течение 5 (пяти) рабочих дней с даты получения документов подписывает их либо направляет Подрядчику мотивированный отказ с перечнем замечаний и сроками их устранения." -> 5.2. Заказчик в течение 5 (пяти) рабочих дней с даты получения документов подписывает их либо направляет Подрядчику мотивированный отказ с перечнем замечаний и сроками их устранения.
A29: 6. ГАРАНТИИ КАЧЕСТВА
A30: ="6.1. Гарантийный срок на выполненные работы составляет "&Параметры!$B$11&" месяца(ев) с даты подписания Сторонами акта по форме КС-2. Гарантия на оборудование — в соответствии с документацией завода-изготовителя." -> 6.1. Гарантийный срок на выполненные работы составляет 24 месяца(ев) с даты подписания Сторонами акта по форме КС-2. Гарантия на оборудование — в соответствии с документацией завода-изготовителя.
A32: 7. ОТВЕТСТВЕННОСТЬ СТОРОН
A33: ="7.1. За нарушение сроков выполнения работ Заказчик вправе требовать от Подрядчика уплаты неустойки в размере "&TEXT(Параметры!$B$13,"0.0%")&" от цены Договора за каждый день просрочки, но не более 10% от цены Договора. За нарушение сроков оплаты Подрядчик вправе требовать от Заказчика неустойку в том же размере от неоплаченной суммы." -> 7.1. За нарушение сроков выполнения работ Заказчик вправе требовать от Подрядчика уплаты неустойки в размере 0.1% от цены Договора за каждый день просрочки, но не более 10% от цены Договора. За нарушение сроков оплаты Подрядчик вправе требовать от Заказчика неустойку в том же размере от неоплаченной суммы.
A35: 8. ПРОЧИЕ УСЛОВИЯ
A36: ="8.1. Споры Сторон разрешаются путём переговоров, а при недостижении согласия — в Арбитражном суде по месту нахождения ответчика с соблюдением претензионного порядка (срок ответа на претензию — 10 рабочих дней)." -> 8.1. Споры Сторон разрешаются путём переговоров, а при недостижении согласия — в Арбитражном суде по месту нахождения ответчика с соблюдением претензионного порядка (срок ответа на претензию — 10 рабочих дней).
A37: ="8.2. Договор составлен в двух экземплярах, имеющих равную юридическую силу, по одному для каждой из Сторон. Приложения: № 1 — Локальная смета № 1; № 2 — Спецификация № 1." -> 8.2. Договор составлен в двух экземплярах, имеющих равную юридическую силу, по одному для каждой из Сторон. Приложения: № 1 — Локальная смета № 1; № 2 — Спецификация № 1.
A39: 9. АДРЕСА И РЕКВИЗИТЫ СТОРОН
A40: ="ЗАКАЗЧИК:" -> ЗАКАЗЧИК: | E40: ="ПОДРЯДЧИК:" -> ПОДРЯДЧИК:
A41: =Параметры!$B$16 -> Общество с ограниченной ответственностью «Специализированный застройщик «Новый квартал» | E41: =Параметры!$B$39 -> Общество с ограниченной ответственностью «ЛифтМонтажСервис»
A42: ="ИНН/КПП: "&Параметры!$B$18&" / "&Параметры!$B$19 -> ИНН/КПП: 7701234567 / 770101001 | E42: ="ИНН/КПП: "&Параметры!$B$41&" / "&Параметры!$B$42 -> ИНН/КПП: 7725678901 / 772501001
A43: ="ОГРН: "&Параметры!$B$20 -> ОГРН: 1157746123456 | E43: ="ОГРН: "&Параметры!$B$43 -> ОГРН: 1187746654321
A44: ="Адрес: "&Параметры!$B$21 -> Адрес: 101000, г. Москва, ул. Мясницкая, д. 10, офис 5 | E44: ="Адрес: "&Параметры!$B$44 -> Адрес: 115280, г. Москва, ул. Ленинская Слобода, д. 19, стр. 2
A45: ="Банк: "&Параметры!$B$22 -> Банк: ПАО «Сбербанк России», г. Москва | E45: ="Банк: "&Параметры!$B$45 -> Банк: АО «Альфа-Банк», г. Москва
A46: ="БИК: "&Параметры!$B$23 -> БИК: 044525225 | E46: ="БИК: "&Параметры!$B$46 -> БИК: 044525593
A47: ="Р/с: "&Параметры!$B$24 -> Р/с: 40702810438000012345 | E47: ="Р/с: "&Параметры!$B$47 -> Р/с: 40702810102300067890
A48: ="К/с: "&Параметры!$B$25 -> К/с: 30101810400000000225 | E48: ="К/с: "&Параметры!$B$48 -> К/с: 30101810200000000593
A49: ="Тел.: "&Параметры!$B$35&", "&Параметры!$B$36 -> Тел.: +7 (495) 123-45-67, info@nk-dev.ru | E49: ="Тел.: "&Параметры!$B$56&", "&Параметры!$B$57 -> Тел.: +7 (495) 987-65-43, office@liftmontag.ru
A51: =Параметры!$B$26 -> Генеральный директор | E51: =Параметры!$B$49 -> Генеральный директор
...
