Workbook
Name СПИСОК_КВАРТИР: 'СПИСОК КВАРТИР'!$B$3:$D$82

Sheet ПАМЯТКА
B2: КОМУ КАКАЯ КВИТАНЦИЯ НУЖНА
B3: ="МКД г. Омск, ул. Магистральная, 2 · всего квартир в списке: "&COUNTA('СПИСОК КВАРТИР'!$B$3:$B$82)
B5: 1. НУЖНА БУМАЖНАЯ КВИТАНЦИЯ | D5: 2. КВИТАНЦИЯ НЕ НУЖНА | F5: 3. КВИТАНЦИЯ В ЭЛЕКТРОННОМ ВИДЕ
B6: печатаем и разносим по почтовым ящикам | D6: платят онлайн по сохранённому шаблону | F6: отправляем PDF на электронную почту
B7: ="Квартир: "&COUNTIF('СПИСОК КВАРТИР'!$C:$C,"Бумажная") | D7: ="Квартир: "&COUNTIF('СПИСОК КВАРТИР'!$C:$C,"Онлайн") | F7: ="Квартир: "&COUNTIF('СПИСОК КВАРТИР'!$C:$C,"Электронная")
B8: =IFERROR("кв. "&INDEX('СПИСОК КВАРТИР'!$B:$B,MATCH(1,'СПИСОК КВАРТИР'!$E:$E,0)),"") | C8: =IFERROR("кв. "&INDEX('СПИСОК КВАРТИР'!$B:$B,MATCH(41,'СПИСОК КВАРТИР'!$E:$E,0)),"") | D8: =IFERROR("кв. "&INDEX('СПИСОК КВАРТИР'!$B:$B,MATCH(1,'СПИСОК КВАРТИР'!$F:$F,0)),"") | E8: =IFERROR("кв. "&INDEX('СПИСОК КВАРТИР'!$B:$B,MATCH(41,'СПИСОК КВАРТИР'!$F:$F,0)),"") | F8: =IFERROR("кв. "&INDEX('СПИСОК КВАРТИР'!$B:$B,MATCH(1,'СПИСОК КВАРТИР'!$G:$G,0)),"") | G8: =IFERROR("кв. "&INDEX('СПИСОК КВАРТИР'!$B:$B,MATCH(41,'СПИСОК КВАРТИР'!$G:$G,0)),"")
B9: =IFERROR("кв. "&INDEX('СПИСОК КВАРТИР'!$B:$B,MATCH(2,'СПИСОК КВАРТИР'!$E:$E,0)),"") | C9: =IFERROR("кв. "&INDEX('СПИСОК КВАРТИР'!$B:$B,MATCH(42,'СПИСОК КВАРТИР'!$E:$E,0)),"") | D9: =IFERROR("кв. "&INDEX('СПИСОК КВАРТИР'!$B:$B,MATCH(2,'СПИСОК КВАРТИР'!$F:$F,0)),"") | E9: =IFERROR("кв. "&INDEX('СПИСОК КВАРТИР'!$B:$B,MATCH(42,'СПИСОК КВАРТИР'!$F:$F,0)),"") | F9: =IFERROR("кв. "&INDEX('СПИСОК КВАРТИР'!$B:$B,MATCH(2,'СПИСОК КВАРТИР'!$G:$G,0)),"") | G9: =IFERROR("кв. "&INDEX('СПИСОК КВАРТИР'!$B:$B,MATCH(42,'СПИСОК КВАРТИР'!$G:$G,0)),"")
B10: =IFERROR("кв. "&INDEX('СПИСОК КВАРТИР'!$B:$B,MATCH(3,'СПИСОК КВАРТИР'!$E:$E,0)),"") | C10: =IFERROR("кв. "&INDEX('СПИСОК КВАРТИР'!$B:$B,MATCH(43,'СПИСОК КВАРТИР'!$E:$E,0)),"") | D10: =IFERROR("кв. "&INDEX('СПИСОК КВАРТИР'!$B:$B,MATCH(3,'СПИСОК КВАРТИР'!$F:$F,0)),"") | E10: =IFERROR("кв. "&INDEX('СПИСОК КВАРТИР'!$B:$B,MATCH(43,'СПИСОК КВАРТИР'!$F:$F,0)),"") | F10: =IFERROR("кв. "&INDEX('СПИСОК КВАРТИР'!$B:$B,MATCH(3,'СПИСОК КВАРТИР'!$G:$G,0)),"") | G10: =IFERROR("кв. "&INDEX('СПИСОК КВАРТИР'!$B:$B,MATCH(43,'СПИСОК КВАРТИР'!$G:$G,0)),"")
B11: =IFERROR("кв. "&INDEX('СПИСОК КВАРТИР'!$B:$B,MATCH(4,'СПИСОК КВАРТИР'!$E:$E,0)),"") | C11: =IFERROR("кв. "&INDEX('СПИСОК КВАРТИР'!$B:$B,MATCH(44,'СПИСОК КВАРТИР'!$E:$E,0)),"") | D11: =IFERROR("кв. "&INDEX('СПИСОК КВАРТИР'!$B:$B,MATCH(4,'СПИСОК КВАРТИР'!$F:$F,0)),"") | E11: =IFERROR("кв. "&INDEX('СПИСОК КВАРТИР'!$B:$B,MATCH(44,'СПИСОК КВАРТИР'!$F:$F,0)),"") | F11: =IFERROR("кв. "&INDEX('СПИСОК КВАРТИР'!$B:$B,MATCH(4,'СПИСОК КВАРТИР'!$G:$G,0)),"") | G11: =IFERROR("кв. "&INDEX('СПИСОК КВАРТИР'!$B:$B,MATCH(44,'СПИСОК КВАРТИР'!$G:$G,0)),"")
B12: =IFERROR("кв. "&INDEX('СПИСОК КВАРТИР'!$B:$B,MATCH(5,'СПИСОК КВАРТИР'!$E:$E,0)),"") | C12: =IFERROR("кв. "&INDEX('СПИСОК КВАРТИР'!$B:$B,MATCH(45,'СПИСОК КВАРТИР'!$E:$E,0)),"") | D12: =IFERROR("кв. "&INDEX('СПИСОК КВАРТИР'!$B:$B,MATCH(5,'СПИСОК КВАРТИР'!$F:$F,0)),"") | E12: =IFERROR("кв. "&INDEX('СПИСОК КВАРТИР'!$B:$B,MATCH(45,'СПИСОК КВАРТИР'!$F:$F,0)),"") | F12: =IFERROR("кв. "&INDEX('СПИСОК КВАРТИР'!$B:$B,MATCH(5,'СПИСОК КВАРТИР'!$G:$G,0)),"") | G12: =IFERROR("кв. "&INDEX('СПИСОК КВАРТИР'!$B:$B,MATCH(45,'СПИСОК КВАРТИР'!$G:$G,0)),"")
B13: =IFERROR("кв. "&INDEX('СПИСОК КВАРТИР'!$B:$B,MATCH(6,'СПИСОК КВАРТИР'!$E:$E,0)),"") | C13: =IFERROR("кв. "&INDEX('СПИСОК КВАРТИР'!$B:$B,MATCH(46,'СПИСОК КВАРТИР'!$E:$E,0)),"") | D13: =IFERROR("кв. "&INDEX('СПИСОК КВАРТИР'!$B:$B,MATCH(6,'СПИСОК КВАРТИР'!$F:$F,0)),"") | E13: =IFERROR("кв. "&INDEX('СПИСОК КВАРТИР'!$B:$B,MATCH(46,'СПИСОК КВАРТИР'!$F:$F,0)),"") | F13: =IFERROR("кв. "&INDEX('СПИСОК КВАРТИР'!$B:$B,MATCH(6,'СПИСОК КВАРТИР'!$G:$G,0)),"") | G13: =IFERROR("кв. "&INDEX('СПИСОК КВАРТИР'!$B:$B,MATCH(46,'СПИСОК КВАРТИР'!$G:$G,0)),"")
B14: =IFERROR("кв. "&INDEX('СПИСОК КВАРТИР'!$B:$B,MATCH(7,'СПИСОК КВАРТИР'!$E:$E,0)),"") | C14: =IFERROR("кв. "&INDEX('СПИСОК КВАРТИР'!$B:$B,MATCH(47,'СПИСОК КВАРТИР'!$E:$E,0)),"") | D14: =IFERROR("кв. "&INDEX('СПИСОК КВАРТИР'!$B:$B,MATCH(7,'СПИСОК КВАРТИР'!$F:$F,0)),"") | E14: =IFERROR("кв. "&INDEX('СПИСОК КВАРТИР'!$B:$B,MATCH(47,'СПИСОК КВАРТИР'!$F:$F,0)),"") | F14: =IFERROR("кв. "&INDEX('СПИСОК КВАРТИР'!$B:$B,MATCH(7,'СПИСОК КВАРТИР'!$G:$G,0)),"") | G14: =IFERROR("кв. "&INDEX('СПИСОК КВАРТИР'!$B:$B,MATCH(47,'СПИСОК КВАРТИР'!$G:$G,0)),"")
B15: =IFERROR("кв. "&INDEX('СПИСОК КВАРТИР'!$B:$B,MATCH(8,'СПИСОК КВАРТИР'!$E:$E,0)),"") | C15: =IFERROR("кв. "&INDEX('СПИСОК КВАРТИР'!$B:$B,MATCH(48,'СПИСОК КВАРТИР'!$E:$E,0)),"") | D15: =IFERROR("кв. "&INDEX('СПИСОК КВАРТИР'!$B:$B,MATCH(8,'СПИСОК КВАРТИР'!$F:$F,0)),"") | E15: =IFERROR("кв. "&INDEX('СПИСОК КВАРТИР'!$B:$B,MATCH(48,'СПИСОК КВАРТИР'!$F:$F,0)),"") | F15: =IFERROR("кв. "&INDEX('СПИСОК КВАРТИР'!$B:$B,MATCH(8,'СПИСОК КВАРТИР'!$G:$G,0)),"") | G15: =IFERROR("кв. "&INDEX('СПИСОК КВАРТИР'!$B:$B,MATCH(48,'СПИСОК КВАРТИР'!$G:$G,0)),"")
B16: =IFERROR("кв. "&INDEX('СПИСОК КВАРТИР'!$B:$B,MATCH(9,'СПИСОК КВАРТИР'!$E:$E,0)),"") | C16: =IFERROR("кв. "&INDEX('СПИСОК КВАРТИР'!$B:$B,MATCH(49,'СПИСОК КВАРТИР'!$E:$E,0)),"") | D16: =IFERROR("кв. "&INDEX('СПИСОК КВАРТИР'!$B:$B,MATCH(9,'СПИСОК КВАРТИР'!$F:$F,0)),"") | E16: =IFERROR("кв. "&INDEX('СПИСОК КВАРТИР'!$B:$B,MATCH(49,'СПИСОК КВАРТИР'!$F:$F,0)),"") | F16: =IFERROR("кв. "&INDEX('СПИСОК КВАРТИР'!$B:$B,MATCH(9,'СПИСОК КВАРТИР'!$G:$G,0)),"") | G16: =IFERROR("кв. "&INDEX('СПИСОК КВАРТИР'!$B:$B,MATCH(49,'СПИСОК КВАРТИР'!$G:$G,0)),"")
B17: =IFERROR("кв. "&INDEX('СПИСОК КВАРТИР'!$B:$B,MATCH(10,'СПИСОК КВАРТИР'!$E:$E,0)),"") | C17: =IFERROR("кв. "&INDEX('СПИСОК КВАРТИР'!$B:$B,MATCH(50,'СПИСОК КВАРТИР'!$E:$E,0)),"") | D17: =IFERROR("кв. "&INDEX('СПИСОК КВАРТИР'!$B:$B,MATCH(10,'СПИСОК КВАРТИР'!$F:$F,0)),"") | E17: =IFERROR("кв. "&INDEX('СПИСОК КВАРТИР'!$B:$B,MATCH(50,'СПИСОК КВАРТИР'!$F:$F,0)),"") | F17: =IFERROR("кв. "&INDEX('СПИСОК КВАРТИР'!$B:$B,MATCH(10,'СПИСОК КВАРТИР'!$G:$G,0)),"") | G17: =IFERROR("кв. "&INDEX('СПИСОК КВАРТИР'!$B:$B,MATCH(50,'СПИСОК КВАРТИР'!$G:$G,0)),"")
B18: =IFERROR("кв. "&INDEX('СПИСОК КВАРТИР'!$B:$B,MATCH(11,'СПИСОК КВАРТИР'!$E:$E,0)),"") | C18: =IFERROR("кв. "&INDEX('СПИСОК КВАРТИР'!$B:$B,MATCH(51,'СПИСОК КВАРТИР'!$E:$E,0)),"") | D18: =IFERROR("кв. "&INDEX('СПИСОК КВАРТИР'!$B:$B,MATCH(11,'СПИСОК КВАРТИР'!$F:$F,0)),"") | E18: =IFERROR("кв. "&INDEX('СПИСОК КВАРТИР'!$B:$B,MATCH(51,'СПИСОК КВАРТИР'!$F:$F,0)),"") | F18: =IFERROR("кв. "&INDEX('СПИСОК КВАРТИР'!$B:$B,MATCH(11,'СПИСОК КВАРТИР'!$G:$G,0)),"") | G18: =IFERROR("кв. "&INDEX('СПИСОК КВАРТИР'!$B:$B,MATCH(51,'СПИСОК КВАРТИР'!$G:$G,0)),"")
B19: =IFERROR("кв. "&INDEX('СПИСОК КВАРТИР'!$B:$B,MATCH(12,'СПИСОК КВАРТИР'!$E:$E,0)),"") | C19: =IFERROR("кв. "&INDEX('СПИСОК КВАРТИР'!$B:$B,MATCH(52,'СПИСОК КВАРТИР'!$E:$E,0)),"") | D19: =IFERROR("кв. "&INDEX('СПИСОК КВАРТИР'!$B:$B,MATCH(12,'СПИСОК КВАРТИР'!$F:$F,0)),"") | E19: =IFERROR("кв. "&INDEX('СПИСОК КВАРТИР'!$B:$B,MATCH(52,'СПИСОК КВАРТИР'!$F:$F,0)),"") | F19: =IFERROR("кв. "&INDEX('СПИСОК КВАРТИР'!$B:$B,MATCH(12,'СПИСОК КВАРТИР'!$G:$G,0)),"") | G19: =IFERROR("кв. "&INDEX('СПИСОК КВАРТИР'!$B:$B,MATCH(52,'СПИСОК КВАРТИР'!$G:$G,0)),"")
B20: =IFERROR("кв. "&INDEX('СПИСОК КВАРТИР'!$B:$B,MATCH(13,'СПИСОК КВАРТИР'!$E:$E,0)),"") | C20: =IFERROR("кв. "&INDEX('СПИСОК КВАРТИР'!$B:$B,MATCH(53,'СПИСОК КВАРТИР'!$E:$E,0)),"") | D20: =IFERROR("кв. "&INDEX('СПИСОК КВАРТИР'!$B:$B,MATCH(13,'СПИСОК КВАРТИР'!$F:$F,0)),"") | E20: =IFERROR("кв. "&INDEX('СПИСОК КВАРТИР'!$B:$B,MATCH(53,'СПИСОК КВАРТИР'!$F:$F,0)),"") | F20: =IFERROR("кв. "&INDEX('СПИСОК КВАРТИР'!$B:$B,MATCH(13,'СПИСОК КВАРТИР'!$G:$G,0)),"") | G20: =IFERROR("кв. "&INDEX('СПИСОК КВАРТИР'!$B:$B,MATCH(53,'СПИСОК КВАРТИР'!$G:$G,0)),"")
B21: =IFERROR("кв. "&INDEX('СПИСОК КВАРТИР'!$B:$B,MATCH(14,'СПИСОК КВАРТИР'!$E:$E,0)),"") | C21: =IFERROR("кв. "&INDEX('СПИСОК КВАРТИР'!$B:$B,MATCH(54,'СПИСОК КВАРТИР'!$E:$E,0)),"") | D21: =IFERROR("кв. "&INDEX('СПИСОК КВАРТИР'!$B:$B,MATCH(14,'СПИСОК КВАРТИР'!$F:$F,0)),"") | E21: =IFERROR("кв. "&INDEX('СПИСОК КВАРТИР'!$B:$B,MATCH(54,'СПИСОК КВАРТИР'!$F:$F,0)),"") | F21: =IFERROR("кв. "&INDEX('СПИСОК КВАРТИР'!$B:$B,MATCH(14,'СПИСОК КВАРТИР'!$G:$G,0)),"") | G21: =IFERROR("кв. "&INDEX('СПИСОК КВАРТИР'!$B:$B,MATCH(54,'СПИСОК КВАРТИР'!$G:$G,0)),"")
B22: =IFERROR("кв. "&INDEX('СПИСОК КВАРТИР'!$B:$B,MATCH(15,'СПИСОК КВАРТИР'!$E:$E,0)),"") | C22: =IFERROR("кв. "&INDEX('СПИСОК КВАРТИР'!$B:$B,MATCH(55,'СПИСОК КВАРТИР'!$E:$E,0)),"") | D22: =IFERROR("кв. "&INDEX('СПИСОК КВАРТИР'!$B:$B,MATCH(15,'СПИСОК КВАРТИР'!$F:$F,0)),"") | E22: =IFERROR("кв. "&INDEX('СПИСОК КВАРТИР'!$B:$B,MATCH(55,'СПИСОК КВАРТИР'!$F:$F,0)),"") | F22: =IFERROR("кв. "&INDEX('СПИСОК КВАРТИР'!$B:$B,MATCH(15,'СПИСОК КВАРТИР'!$G:$G,0)),"") | G22: =IFERROR("кв. "&INDEX('СПИСОК КВАРТИР'!$B:$B,MATCH(55,'СПИСОК КВАРТИР'!$G:$G,0)),"")
B23: =IFERROR("кв. "&INDEX('СПИСОК КВАРТИР'!$B:$B,MATCH(16,'СПИСОК КВАРТИР'!$E:$E,0)),"") | C23: =IFERROR("кв. "&INDEX('СПИСОК КВАРТИР'!$B:$B,MATCH(56,'СПИСОК КВАРТИР'!$E:$E,0)),"") | D23: =IFERROR("кв. "&INDEX('СПИСОК КВАРТИР'!$B:$B,MATCH(16,'СПИСОК КВАРТИР'!$F:$F,0)),"") | E23: =IFERROR("кв. "&INDEX('СПИСОК КВАРТИР'!$B:$B,MATCH(56,'СПИСОК КВАРТИР'!$F:$F,0)),"") | F23: =IFERROR("кв. "&INDEX('СПИСОК КВАРТИР'!$B:$B,MATCH(16,'СПИСОК КВАРТИР'!$G:$G,0)),"") | G23: =IFERROR("кв. "&INDEX('СПИСОК КВАРТИР'!$B:$B,MATCH(56,'СПИСОК КВАРТИР'!$G:$G,0)),"")
B24: =IFERROR("кв. "&INDEX('СПИСОК КВАРТИР'!$B:$B,MATCH(17,'СПИСОК КВАРТИР'!$E:$E,0)),"") | C24: =IFERROR("кв. "&INDEX('СПИСОК КВАРТИР'!$B:$B,MATCH(57,'СПИСОК КВАРТИР'!$E:$E,0)),"") | D24: =IFERROR("кв. "&INDEX('СПИСОК КВАРТИР'!$B:$B,MATCH(17,'СПИСОК КВАРТИР'!$F:$F,0)),"") | E24: =IFERROR("кв. "&INDEX('СПИСОК КВАРТИР'!$B:$B,MATCH(57,'СПИСОК КВАРТИР'!$F:$F,0)),"") | F24: =IFERROR("кв. "&INDEX('СПИСОК КВАРТИР'!$B:$B,MATCH(17,'СПИСОК КВАРТИР'!$G:$G,0)),"") | G24: =IFERROR("кв. "&INDEX('СПИСОК КВАРТИР'!$B:$B,MATCH(57,'СПИСОК КВАРТИР'!$G:$G,0)),"")
B25: =IFERROR("кв. "&INDEX('СПИСОК КВАРТИР'!$B:$B,MATCH(18,'СПИСОК КВАРТИР'!$E:$E,0)),"") | C25: =IFERROR("кв. "&INDEX('СПИСОК КВАРТИР'!$B:$B,MATCH(58,'СПИСОК КВАРТИР'!$E:$E,0)),"") | D25: =IFERROR("кв. "&INDEX('СПИСОК КВАРТИР'!$B:$B,MATCH(18,'СПИСОК КВАРТИР'!$F:$F,0)),"") | E25: =IFERROR("кв. "&INDEX('СПИСОК КВАРТИР'!$B:$B,MATCH(58,'СПИСОК КВАРТИР'!$F:$F,0)),"") | F25: =IFERROR("кв. "&INDEX('СПИСОК КВАРТИР'!$B:$B,MATCH(18,'СПИСОК КВАРТИР'!$G:$G,0)),"") | G25: =IFERROR("кв. "&INDEX('СПИСОК КВАРТИР'!$B:$B,MATCH(58,'СПИСОК КВАРТИР'!$G:$G,0)),"")
B26: =IFERROR("кв. "&INDEX('СПИСОК КВАРТИР'!$B:$B,MATCH(19,'СПИСОК КВАРТИР'!$E:$E,0)),"") | C26: =IFERROR("кв. "&INDEX('СПИСОК КВАРТИР'!$B:$B,MATCH(59,'СПИСОК КВАРТИР'!$E:$E,0)),"") | D26: =IFERROR("кв. "&INDEX('СПИСОК КВАРТИР'!$B:$B,MATCH(19,'СПИСОК КВАРТИР'!$F:$F,0)),"") | E26: =IFERROR("кв. "&INDEX('СПИСОК КВАРТИР'!$B:$B,MATCH(59,'СПИСОК КВАРТИР'!$F:$F,0)),"") | F26: =IFERROR("кв. "&INDEX('СПИСОК КВАРТИР'!$B:$B,MATCH(19,'СПИСОК КВАРТИР'!$G:$G,0)),"") | G26: =IFERROR("кв. "&INDEX('СПИСОК КВАРТИР'!$B:$B,MATCH(59,'СПИСОК КВАРТИР'!$G:$G,0)),"")
B27: =IFERROR("кв. "&INDEX('СПИСОК КВАРТИР'!$B:$B,MATCH(20,'СПИСОК КВАРТИР'!$E:$E,0)),"") | C27: =IFERROR("кв. "&INDEX('СПИСОК КВАРТИР'!$B:$B,MATCH(60,'СПИСОК КВАРТИР'!$E:$E,0)),"") | D27: =IFERROR("кв. "&INDEX('СПИСОК КВАРТИР'!$B:$B,MATCH(20,'СПИСОК КВАРТИР'!$F:$F,0)),"") | E27: =IFERROR("кв. "&INDEX('СПИСОК КВАРТИР'!$B:$B,MATCH(60,'СПИСОК КВАРТИР'!$F:$F,0)),"") | F27: =IFERROR("кв. "&INDEX('СПИСОК КВАРТИР'!$B:$B,MATCH(20,'СПИСОК КВАРТИР'!$G:$G,0)),"") | G27: =IFERROR("кв. "&INDEX('СПИСОК КВАРТИР'!$B:$B,MATCH(60,'СПИСОК КВАРТИР'!$G:$G,0)),"")
B28: =IFERROR("кв. "&INDEX('СПИСОК КВАРТИР'!$B:$B,MATCH(21,'СПИСОК КВАРТИР'!$E:$E,0)),"") | C28: =IFERROR("кв. "&INDEX('СПИСОК КВАРТИР'!$B:$B,MATCH(61,'СПИСОК КВАРТИР'!$E:$E,0)),"") | D28: =IFERROR("кв. "&INDEX('СПИСОК КВАРТИР'!$B:$B,MATCH(21,'СПИСОК КВАРТИР'!$F:$F,0)),"") | E28: =IFERROR("кв. "&INDEX('СПИСОК КВАРТИР'!$B:$B,MATCH(61,'СПИСОК КВАРТИР'!$F:$F,0)),"") | F28: =IFERROR("кв. "&INDEX('СПИСОК КВАРТИР'!$B:$B,MATCH(21,'СПИСОК КВАРТИР'!$G:$G,0)),"") | G28: =IFERROR("кв. "&INDEX('СПИСОК КВАРТИР'!$B:$B,MATCH(61,'СПИСОК КВАРТИР'!$G:$G,0)),"")
B29: =IFERROR("кв. "&INDEX('СПИСОК КВАРТИР'!$B:$B,MATCH(22,'СПИСОК КВАРТИР'!$E:$E,0)),"") | C29: =IFERROR("кв. "&INDEX('СПИСОК КВАРТИР'!$B:$B,MATCH(62,'СПИСОК КВАРТИР'!$E:$E,0)),"") | D29: =IFERROR("кв. "&INDEX('СПИСОК КВАРТИР'!$B:$B,MATCH(22,'СПИСОК КВАРТИР'!$F:$F,0)),"") | E29: =IFERROR("кв. "&INDEX('СПИСОК КВАРТИР'!$B:$B,MATCH(62,'СПИСОК КВАРТИР'!$F:$F,0)),"") | F29: =IFERROR("кв. "&INDEX('СПИСОК КВАРТИР'!$B:$B,MATCH(22,'СПИСОК КВАРТИР'!$G:$G,0)),"") | G29: =IFERROR("кв. "&INDEX('СПИСОК КВАРТИР'!$B:$B,MATCH(62,'СПИСОК КВАРТИР'!$G:$G,0)),"")
B30: =IFERROR("кв. "&INDEX('СПИСОК КВАРТИР'!$B:$B,MATCH(23,'СПИСОК КВАРТИР'!$E:$E,0)),"") | C30: =IFERROR("кв. "&INDEX('СПИСОК КВАРТИР'!$B:$B,MATCH(63,'СПИСОК КВАРТИР'!$E:$E,0)),"") | D30: =IFERROR("кв. "&INDEX('СПИСОК КВАРТИР'!$B:$B,MATCH(23,'СПИСОК КВАРТИР'!$F:$F,0)),"") | E30: =IFERROR("кв. "&INDEX('СПИСОК КВАРТИР'!$B:$B,MATCH(63,'СПИСОК КВАРТИР'!$F:$F,0)),"") | F30: =IFERROR("кв. "&INDEX('СПИСОК КВАРТИР'!$B:$B,MATCH(23,'СПИСОК КВАРТИР'!$G:$G,0)),"") | G30: =IFERROR("кв. "&INDEX('СПИСОК КВАРТИР'!$B:$B,MATCH(63,'СПИСОК КВАРТИР'!$G:$G,0)),"")
B31: =IFERROR("кв. "&INDEX('СПИСОК КВАРТИР'!$B:$B,MATCH(24,'СПИСОК КВАРТИР'!$E:$E,0)),"") | C31: =IFERROR("кв. "&INDEX('СПИСОК КВАРТИР'!$B:$B,MATCH(64,'СПИСОК КВАРТИР'!$E:$E,0)),"") | D31: =IFERROR("кв. "&INDEX('СПИСОК КВАРТИР'!$B:$B,MATCH(24,'СПИСОК КВАРТИР'!$F:$F,0)),"") | E31: =IFERROR("кв. "&INDEX('СПИСОК КВАРТИР'!$B:$B,MATCH(64,'СПИСОК КВАРТИР'!$F:$F,0)),"") | F31: =IFERROR("кв. "&INDEX('СПИСОК КВАРТИР'!$B:$B,MATCH(24,'СПИСОК КВАРТИР'!$G:$G,0)),"") | G31: =IFERROR("кв. "&INDEX('СПИСОК КВАРТИР'!$B:$B,MATCH(64,'СПИСОК КВАРТИР'!$G:$G,0)),"")
B32: =IFERROR("кв. "&INDEX('СПИСОК КВАРТИР'!$B:$B,MATCH(25,'СПИСОК КВАРТИР'!$E:$E,0)),"") | C32: =IFERROR("кв. "&INDEX('СПИСОК КВАРТИР'!$B:$B,MATCH(65,'СПИСОК КВАРТИР'!$E:$E,0)),"") | D32: =IFERROR("кв. "&INDEX('СПИСОК КВАРТИР'!$B:$B,MATCH(25,'СПИСОК КВАРТИР'!$F:$F,0)),"") | E32: =IFERROR("кв. "&INDEX('СПИСОК КВАРТИР'!$B:$B,MATCH(65,'СПИСОК КВАРТИР'!$F:$F,0)),"") | F32: =IFERROR("кв. "&INDEX('СПИСОК КВАРТИР'!$B:$B,MATCH(25,'СПИСОК КВАРТИР'!$G:$G,0)),"") | G32: =IFERROR("кв. "&INDEX('СПИСОК КВАРТИР'!$B:$B,MATCH(65,'СПИСОК КВАРТИР'!$G:$G,0)),"")
B33: =IFERROR("кв. "&INDEX('СПИСОК КВАРТИР'!$B:$B,MATCH(26,'СПИСОК КВАРТИР'!$E:$E,0)),"") | C33: =IFERROR("кв. "&INDEX('СПИСОК КВАРТИР'!$B:$B,MATCH(66,'СПИСОК КВАРТИР'!$E:$E,0)),"") | D33: =IFERROR("кв. "&INDEX('СПИСОК КВАРТИР'!$B:$B,MATCH(26,'СПИСОК КВАРТИР'!$F:$F,0)),"") | E33: =IFERROR("кв. "&INDEX('СПИСОК КВАРТИР'!$B:$B,MATCH(66,'СПИСОК КВАРТИР'!$F:$F,0)),"") | F33: =IFERROR("кв. "&INDEX('СПИСОК КВАРТИР'!$B:$B,MATCH(26,'СПИСОК КВАРТИР'!$G:$G,0)),"") | G33: =IFERROR("кв. "&INDEX('СПИСОК КВАРТИР'!$B:$B,MATCH(66,'СПИСОК КВАРТИР'!$G:$G,0)),"")
B34: =IFERROR("кв. "&INDEX('СПИСОК КВАРТИР'!$B:$B,MATCH(27,'СПИСОК КВАРТИР'!$E:$E,0)),"") | C34: =IFERROR("кв. "&INDEX('СПИСОК КВАРТИР'!$B:$B,MATCH(67,'СПИСОК КВАРТИР'!$E:$E,0)),"") | D34: =IFERROR("кв. "&INDEX('СПИСОК КВАРТИР'!$B:$B,MATCH(27,'СПИСОК КВАРТИР'!$F:$F,0)),"") | E34: =IFERROR("кв. "&INDEX('СПИСОК КВАРТИР'!$B:$B,MATCH(67,'СПИСОК КВАРТИР'!$F:$F,0)),"") | F34: =IFERROR("кв. "&INDEX('СПИСОК КВАРТИР'!$B:$B,MATCH(27,'СПИСОК КВАРТИР'!$G:$G,0)),"") | G34: =IFERROR("кв. "&INDEX('СПИСОК КВАРТИР'!$B:$B,MATCH(67,'СПИСОК КВАРТИР'!$G:$G,0)),"")
B35: =IFERROR("кв. "&INDEX('СПИСОК КВАРТИР'!$B:$B,MATCH(28,'СПИСОК КВАРТИР'!$E:$E,0)),"") | C35: =IFERROR("кв. "&INDEX('СПИСОК КВАРТИР'!$B:$B,MATCH(68,'СПИСОК КВАРТИР'!$E:$E,0)),"") | D35: =IFERROR("кв. "&INDEX('СПИСОК КВАРТИР'!$B:$B,MATCH(28,'СПИСОК КВАРТИР'!$F:$F,0)),"") | E35: =IFERROR("кв. "&INDEX('СПИСОК КВАРТИР'!$B:$B,MATCH(68,'СПИСОК КВАРТИР'!$F:$F,0)),"") | F35: =IFERROR("кв. "&INDEX('СПИСОК КВАРТИР'!$B:$B,MATCH(28,'СПИСОК КВАРТИР'!$G:$G,0)),"") | G35: =IFERROR("кв. "&INDEX('СПИСОК КВАРТИР'!$B:$B,MATCH(68,'СПИСОК КВАРТИР'!$G:$G,0)),"")
B36: =IFERROR("кв. "&INDEX('СПИСОК КВАРТИР'!$B:$B,MATCH(29,'СПИСОК КВАРТИР'!$E:$E,0)),"") | C36: =IFERROR("кв. "&INDEX('СПИСОК КВАРТИР'!$B:$B,MATCH(69,'СПИСОК КВАРТИР'!$E:$E,0)),"") | D36: =IFERROR("кв. "&INDEX('СПИСОК КВАРТИР'!$B:$B,MATCH(29,'СПИСОК КВАРТИР'!$F:$F,0)),"") | E36: =IFERROR("кв. "&INDEX('СПИСОК КВАРТИР'!$B:$B,MATCH(69,'СПИСОК КВАРТИР'!$F:$F,0)),"") | F36: =IFERROR("кв. "&INDEX('СПИСОК КВАРТИР'!$B:$B,MATCH(29,'СПИСОК КВАРТИР'!$G:$G,0)),"") | G36: =IFERROR("кв. "&INDEX('СПИСОК КВАРТИР'!$B:$B,MATCH(69,'СПИСОК КВАРТИР'!$G:$G,0)),"")
B37: =IFERROR("кв. "&INDEX('СПИСОК КВАРТИР'!$B:$B,MATCH(30,'СПИСОК КВАРТИР'!$E:$E,0)),"") | C37: =IFERROR("кв. "&INDEX('СПИСОК КВАРТИР'!$B:$B,MATCH(70,'СПИСОК КВАРТИР'!$E:$E,0)),"") | D37: =IFERROR("кв. "&INDEX('СПИСОК КВАРТИР'!$B:$B,MATCH(30,'СПИСОК КВАРТИР'!$F:$F,0)),"") | E37: =IFERROR("кв. "&INDEX('СПИСОК КВАРТИР'!$B:$B,MATCH(70,'СПИСОК КВАРТИР'!$F:$F,0)),"") | F37: =IFERROR("кв. "&INDEX('СПИСОК КВАРТИР'!$B:$B,MATCH(30,'СПИСОК КВАРТИР'!$G:$G,0)),"") | G37: =IFERROR("кв. "&INDEX('СПИСОК КВАРТИР'!$B:$B,MATCH(70,'СПИСОК КВАРТИР'!$G:$G,0)),"")
B38: =IFERROR("кв. "&INDEX('СПИСОК КВАРТИР'!$B:$B,MATCH(31,'СПИСОК КВАРТИР'!$E:$E,0)),"") | C38: =IFERROR("кв. "&INDEX('СПИСОК КВАРТИР'!$B:$B,MATCH(71,'СПИСОК КВАРТИР'!$E:$E,0)),"") | D38: =IFERROR("кв. "&INDEX('СПИСОК КВАРТИР'!$B:$B,MATCH(31,'СПИСОК КВАРТИР'!$F:$F,0)),"") | E38: =IFERROR("кв. "&INDEX('СПИСОК КВАРТИР'!$B:$B,MATCH(71,'СПИСОК КВАРТИР'!$F:$F,0)),"") | F38: =IFERROR("кв. "&INDEX('СПИСОК КВАРТИР'!$B:$B,MATCH(31,'СПИСОК КВАРТИР'!$G:$G,0)),"") | G38: =IFERROR("кв. "&INDEX('СПИСОК КВАРТИР'!$B:$B,MATCH(71,'СПИСОК КВАРТИР'!$G:$G,0)),"")
B39: =IFERROR("кв. "&INDEX('СПИСОК КВАРТИР'!$B:$B,MATCH(32,'СПИСОК КВАРТИР'!$E:$E,0)),"") | C39: =IFERROR("кв. "&INDEX('СПИСОК КВАРТИР'!$B:$B,MATCH(72,'СПИСОК КВАРТИР'!$E:$E,0)),"") | D39: =IFERROR("кв. "&INDEX('СПИСОК КВАРТИР'!$B:$B,MATCH(32,'СПИСОК КВАРТИР'!$F:$F,0)),"") | E39: =IFERROR("кв. "&INDEX('СПИСОК КВАРТИР'!$B:$B,MATCH(72,'СПИСОК КВАРТИР'!$F:$F,0)),"") | F39: =IFERROR("кв. "&INDEX('СПИСОК КВАРТИР'!$B:$B,MATCH(32,'СПИСОК КВАРТИР'!$G:$G,0)),"") | G39: =IFERROR("кв. "&INDEX('СПИСОК КВАРТИР'!$B:$B,MATCH(72,'СПИСОК КВАРТИР'!$G:$G,0)),"")
B40: =IFERROR("кв. "&INDEX('СПИСОК КВАРТИР'!$B:$B,MATCH(33,'СПИСОК КВАРТИР'!$E:$E,0)),"") | C40: =IFERROR("кв. "&INDEX('СПИСОК КВАРТИР'!$B:$B,MATCH(73,'СПИСОК КВАРТИР'!$E:$E,0)),"") | D40: =IFERROR("кв. "&INDEX('СПИСОК КВАРТИР'!$B:$B,MATCH(33,'СПИСОК КВАРТИР'!$F:$F,0)),"") | E40: =IFERROR("кв. "&INDEX('СПИСОК КВАРТИР'!$B:$B,MATCH(73,'СПИСОК КВАРТИР'!$F:$F,0)),"") | F40: =IFERROR("кв. "&INDEX('СПИСОК КВАРТИР'!$B:$B,MATCH(33,'СПИСОК КВАРТИР'!$G:$G,0)),"") | G40: =IFERROR("кв. "&INDEX('СПИСОК КВАРТИР'!$B:$B,MATCH(73,'СПИСОК КВАРТИР'!$G:$G,0)),"")
B41: =IFERROR("кв. "&INDEX('СПИСОК КВАРТИР'!$B:$B,MATCH(34,'СПИСОК КВАРТИР'!$E:$E,0)),"") | C41: =IFERROR("кв. "&INDEX('СПИСОК КВАРТИР'!$B:$B,MATCH(74,'СПИСОК КВАРТИР'!$E:$E,0)),"") | D41: =IFERROR("кв. "&INDEX('СПИСОК КВАРТИР'!$B:$B,MATCH(34,'СПИСОК КВАРТИР'!$F:$F,0)),"") | E41: =IFERROR("кв. "&INDEX('СПИСОК КВАРТИР'!$B:$B,MATCH(74,'СПИСОК КВАРТИР'!$F:$F,0)),"") | F41: =IFERROR("кв. "&INDEX('СПИСОК КВАРТИР'!$B:$B,MATCH(34,'СПИСОК КВАРТИР'!$G:$G,0)),"") | G41: =IFERROR("кв. "&INDEX('СПИСОК КВАРТИР'!$B:$B,MATCH(74,'СПИСОК КВАРТИР'!$G:$G,0)),"")
B42: =IFERROR("кв. "&INDEX('СПИСОК КВАРТИР'!$B:$B,MATCH(35,'СПИСОК КВАРТИР'!$E:$E,0)),"") | C42: =IFERROR("кв. "&INDEX('СПИСОК КВАРТИР'!$B:$B,MATCH(75,'СПИСОК КВАРТИР'!$E:$E,0)),"") | D42: =IFERROR("кв. "&INDEX('СПИСОК КВАРТИР'!$B:$B,MATCH(35,'СПИСОК КВАРТИР'!$F:$F,0)),"") | E42: =IFERROR("кв. "&INDEX('СПИСОК КВАРТИР'!$B:$B,MATCH(75,'СПИСОК КВАРТИР'!$F:$F,0)),"") | F42: =IFERROR("кв. "&INDEX('СПИСОК КВАРТИР'!$B:$B,MATCH(35,'СПИСОК КВАРТИР'!$G:$G,0)),"") | G42: =IFERROR("кв. "&INDEX('СПИСОК КВАРТИР'!$B:$B,MATCH(75,'СПИСОК КВАРТИР'!$G:$G,0)),"")
...

Sheet Sheet

Sheet СПИСОК КВАРТИР
B1: СПИСОК КВАРТИР — ЗДЕСЬ МЕНЯЕМ СТАТУС
B2: Квартира | C2: Статус | D2: Примечание (собственник, почта, договорённости) | E2: № в «Бумажная» | F2: № в «Онлайн» | G2: № в «Электронная»
B3: 1 | C3: Бумажная | E3: =IF($C3="Бумажная",COUNTIF($C$3:$C3,"Бумажная"),"") | F3: =IF($C3="Онлайн",COUNTIF($C$3:$C3,"Онлайн"),"") | G3: =IF($C3="Электронная",COUNTIF($C$3:$C3,"Электронная"),"")
B4: 2 | C4: Бумажная | E4: =IF($C4="Бумажная",COUNTIF($C$3:$C4,"Бумажная"),"") | F4: =IF($C4="Онлайн",COUNTIF($C$3:$C4,"Онлайн"),"") | G4: =IF($C4="Электронная",COUNTIF($C$3:$C4,"Электронная"),"")
B5: 3 | C5: Бумажная | E5: =IF($C5="Бумажная",COUNTIF($C$3:$C5,"Бумажная"),"") | F5: =IF($C5="Онлайн",COUNTIF($C$3:$C5,"Онлайн"),"") | G5: =IF($C5="Электронная",COUNTIF($C$3:$C5,"Электронная"),"")
B6: 4 | C6: Бумажная | E6: =IF($C6="Бумажная",COUNTIF($C$3:$C6,"Бумажная"),"") | F6: =IF($C6="Онлайн",COUNTIF($C$3:$C6,"Онлайн"),"") | G6: =IF($C6="Электронная",COUNTIF($C$3:$C6,"Электронная"),"")
B7: 5 | C7: Бумажная | E7: =IF($C7="Бумажная",COUNTIF($C$3:$C7,"Бумажная"),"") | F7: =IF($C7="Онлайн",COUNTIF($C$3:$C7,"Онлайн"),"") | G7: =IF($C7="Электронная",COUNTIF($C$3:$C7,"Электронная"),"")
B8: 6 | C8: Бумажная | E8: =IF($C8="Бумажная",COUNTIF($C$3:$C8,"Бумажная"),"") | F8: =IF($C8="Онлайн",COUNTIF($C$3:$C8,"Онлайн"),"") | G8: =IF($C8="Электронная",COUNTIF($C$3:$C8,"Электронная"),"")
B9: 7 | C9: Бумажная | E9: =IF($C9="Бумажная",COUNTIF($C$3:$C9,"Бумажная"),"") | F9: =IF($C9="Онлайн",COUNTIF($C$3:$C9,"Онлайн"),"") | G9: =IF($C9="Электронная",COUNTIF($C$3:$C9,"Электронная"),"")
B10: 8 | C10: Бумажная | E10: =IF($C10="Бумажная",COUNTIF($C$3:$C10,"Бумажная"),"") | F10: =IF($C10="Онлайн",COUNTIF($C$3:$C10,"Онлайн"),"") | G10: =IF($C10="Электронная",COUNTIF($C$3:$C10,"Электронная"),"")
B11: 9 | C11: Бумажная | E11: =IF($C11="Бумажная",COUNTIF($C$3:$C11,"Бумажная"),"") | F11: =IF($C11="Онлайн",COUNTIF($C$3:$C11,"Онлайн"),"") | G11: =IF($C11="Электронная",COUNTIF($C$3:$C11,"Электронная"),"")
B12: 10 | C12: Бумажная | E12: =IF($C12="Бумажная",COUNTIF($C$3:$C12,"Бумажная"),"") | F12: =IF($C12="Онлайн",COUNTIF($C$3:$C12,"Онлайн"),"") | G12: =IF($C12="Электронная",COUNTIF($C$3:$C12,"Электронная"),"")
B13: 11 | C13: Бумажная | E13: =IF($C13="Бумажная",COUNTIF($C$3:$C13,"Бумажная"),"") | F13: =IF($C13="Онлайн",COUNTIF($C$3:$C13,"Онлайн"),"") | G13: =IF($C13="Электронная",COUNTIF($C$3:$C13,"Электронная"),"")
B14: 12 | C14: Бумажная | E14: =IF($C14="Бумажная",COUNTIF($C$3:$C14,"Бумажная"),"") | F14: =IF($C14="Онлайн",COUNTIF($C$3:$C14,"Онлайн"),"") | G14: =IF($C14="Электронная",COUNTIF($C$3:$C14,"Электронная"),"")
... B48: 46 | C48: Бумажная | E48: =IF($C48="Бумажная",COUNTIF($C$3:$C48,"Бумажная"),"") | F48: =IF($C48="Онлайн",COUNTIF($C$3:$C48,"Онлайн"),"") | G48: =IF($C48="Электронная",COUNTIF($C$3:$C48,"Электронная"),"")
B49: 47 | C49: Электронная | D49: Департамент жилищной политики Администрации города Омска | E49: =IF($C49="Бумажная",COUNTIF($C$3:$C49,"Бумажная"),"") | F49: =IF($C49="Онлайн",COUNTIF($C$3:$C49,"Онлайн"),"") | G49: =IF($C49="Электронная",COUNTIF($C$3:$C49,"Электронная"),"")
B50: 48 | C50: Бумажная | E50: =IF($C50="Бумажная",COUNTIF($C$3:$C50,"Бумажная"),"") | F50: =IF($C50="Онлайн",COUNTIF($C$3:$C50,"Онлайн"),"") | G50: =IF($C50="Электронная",COUNTIF($C$3:$C50,"Электронная"),"")
B51: 49 | C51: Онлайн | D51: Председатель совета дома | E51: =IF($C51="Бумажная",COUNTIF($C$3:$C51,"Бумажная"),"") | F51: =IF($C51="Онлайн",COUNTIF($C$3:$C51,"Онлайн"),"") | G51: =IF($C51="Электронная",COUNTIF($C$3:$C51,"Электронная"),"")
B52: 50 | C52: Бумажная | E52: =IF($C52="Бумажная",COUNTIF($C$3:$C52,"Бумажная"),"") | F52: =IF($C52="Онлайн",COUNTIF($C$3:$C52,"Онлайн"),"") | G52: =IF($C52="Электронная",COUNTIF($C$3:$C52,"Электронная"),"")
B53: 51 | C53: Бумажная | E53: =IF($C53="Бумажная",COUNTIF($C$3:$C53,"Бумажная"),"") | F53: =IF($C53="Онлайн",COUNTIF($C$3:$C53,"Онлайн"),"") | G53: =IF($C53="Электронная",COUNTIF($C$3:$C53,"Электронная"),"")
B54: 52 | C54: Бумажная | E54: =IF($C54="Бумажная",COUNTIF($C$3:$C54,"Бумажная"),"") | F54: =IF($C54="Онлайн",COUNTIF($C$3:$C54,"Онлайн"),"") | G54: =IF($C54="Электронная",COUNTIF($C$3:$C54,"Электронная"),"")
B55: 53 | C55: Бумажная | E55: =IF($C55="Бумажная",COUNTIF($C$3:$C55,"Бумажная"),"") | F55: =IF($C55="Онлайн",COUNTIF($C$3:$C55,"Онлайн"),"") | G55: =IF($C55="Электронная",COUNTIF($C$3:$C55,"Электронная"),"")
B56: 54 | C56: Бумажная | E56: =IF($C56="Бумажная",COUNTIF($C$3:$C56,"Бумажная"),"") | F56: =IF($C56="Онлайн",COUNTIF($C$3:$C56,"Онлайн"),"") | G56: =IF($C56="Электронная",COUNTIF($C$3:$C56,"Электронная"),"")
B57: 55 | C57: Бумажная | E57: =IF($C57="Бумажная",COUNTIF($C$3:$C57,"Бумажная"),"") | F57: =IF($C57="Онлайн",COUNTIF($C$3:$C57,"Онлайн"),"") | G57: =IF($C57="Электронная",COUNTIF($C$3:$C57,"Электронная"),"")
B58: 56 | C58: Бумажная | E58: =IF($C58="Бумажная",COUNTIF($C$3:$C58,"Бумажная"),"") | F58: =IF($C58="Онлайн",COUNTIF($C$3:$C58,"Онлайн"),"") | G58: =IF($C58="Электронная",COUNTIF($C$3:$C58,"Электронная"),"")
B59: 57 | C59: Бумажная | E59: =IF($C59="Бумажная",COUNTIF($C$3:$C59,"Бумажная"),"") | F59: =IF($C59="Онлайн",COUNTIF($C$3:$C59,"Онлайн"),"") | G59: =IF($C59="Электронная",COUNTIF($C$3:$C59,"Электронная"),"")
B60: 58 | C60: Бумажная | E60: =IF($C60="Бумажная",COUNTIF($C$3:$C60,"Бумажная"),"") | F60: =IF($C60="Онлайн",COUNTIF($C$3:$C60,"Онлайн"),"") | G60: =IF($C60="Электронная",COUNTIF($C$3:$C60,"Электронная"),"")
B61: 59 | C61: Бумажная | E61: =IF($C61="Бумажная",COUNTIF($C$3:$C61,"Бумажная"),"") | F61: =IF($C61="Онлайн",COUNTIF($C$3:$C61,"Онлайн"),"") | G61: =IF($C61="Электронная",COUNTIF($C$3:$C61,"Электронная"),"")
B62: 60 | C62: Бумажная | E62: =IF($C62="Бумажная",COUNTIF($C$3:$C62,"Бумажная"),"") | F62: =IF($C62="Онлайн",COUNTIF($C$3:$C62,"Онлайн"),"") | G62: =IF($C62="Электронная",COUNTIF($C$3:$C62,"Электронная"),"")
B63: 61 | C63: Бумажная | E63: =IF($C63="Бумажная",COUNTIF($C$3:$C63,"Бумажная"),"") | F63: =IF($C63="Онлайн",COUNTIF($C$3:$C63,"Онлайн"),"") | G63: =IF($C63="Электронная",COUNTIF($C$3:$C63,"Электронная"),"")
... B82: 80 | C82: Бумажная | E82: =IF($C82="Бумажная",COUNTIF($C$3:$C82,"Бумажная"),"") | F82: =IF($C82="Онлайн",COUNTIF($C$3:$C82,"Онлайн"),"") | G82: =IF($C82="Электронная",COUNTIF($C$3:$C82,"Электронная"),"")
B84: Чтобы квартира переехала в другой столбец памятки, поменяйте её статус в столбце «Статус» — вручную переносить ничего не нужно. Столбцы E–G служебные: по ним памятка собирает списки, их можно скрыть, но не удалять. Лишние строки просто очистите, новые квартиры дописывайте ниже и протяните формулы в E–G.
